06/01/2024 22:21:38|INFO    |root                            |BAZARR trying to connect to Sonarr SignalR feed...|
06/01/2024 22:21:38|INFO    |root                            |BAZARR trying to connect to Radarr SignalR feed...|
06/01/2024 22:21:38|INFO    |root                            |BAZARR is started and waiting for request on http://***.***.***.***:6767|
06/01/2024 22:36:21|ERROR   |root                            |BAZARR Error trying to get rootfolder from Sonarr. Connection Error.|'Traceback (most recent call last):\n  File "/app/bazarr/bin/bazarr/../libs/urllib3/connection.py", line 174, in _new_conn\n    conn = connection.create_connection(\n           ^^^^^^^^^^^^^^^^^^^^^^^^^^^^^\n  File "/app/bazarr/bin/bazarr/../libs/subliminal_patch/http.py", line 325, in patched_create_connection\n    return _orig_create_connection(address, *args, **kwargs)\n           ^^^^^^^^^^^^^^^^^^^^^^^^^^^^^^^^^^^^^^^^^^^^^^^^^\n  File "/app/bazarr/bin/bazarr/../libs/urllib3/util/connection.py", line 95, in create_connection\n    raise err\n  File "/app/bazarr/bin/bazarr/../libs/urllib3/util/connection.py", line 85, in create_connection\n    sock.connect(sa)\nTimeoutError: timed out\n\nDuring handling of the above exception, another exception occurred:\n\nTraceback (most recent call last):\n  File "/app/bazarr/bin/bazarr/../libs/urllib3/connectionpool.py", line 703, in urlopen\n    httplib_response = self._make_request(\n                       ^^^^^^^^^^^^^^^^^^^\n  File "/app/bazarr/bin/bazarr/../libs/urllib3/connectionpool.py", line 398, in _make_request\n    conn.request(method, url, **httplib_request_kw)\n  File "/app/bazarr/bin/bazarr/../libs/urllib3/connection.py", line 239, in request\n    super(HTTPConnection, self).request(method, url, body=body, headers=headers)\n  File "/usr/lib/python3.11/http/client.py", line 1286, in request\n    self._send_request(method, url, body, headers, encode_chunked)\n  File "/usr/lib/python3.11/http/client.py", line 1332, in _send_request\n    self.endheaders(body, encode_chunked=encode_chunked)\n  File "/usr/lib/python3.11/http/client.py", line 1281, in endheaders\n    self._send_output(message_body, encode_chunked=encode_chunked)\n  File "/usr/lib/python3.11/http/client.py", line 1041, in _send_output\n    self.send(msg)\n  File "/usr/lib/python3.11/http/client.py", line 979, in send\n    self.connect()\n  File "/app/bazarr/bin/bazarr/../libs/urllib3/connection.py", line 205, in connect\n    conn = self._new_conn()\n           ^^^^^^^^^^^^^^^^\n  File "/app/bazarr/bin/bazarr/../libs/urllib3/connection.py", line 179, in _new_conn\n    raise ConnectTimeoutError(\nurllib3.exceptions.ConnectTimeoutError: (<urllib3.connection.HTTPConnection object at 0x7f1914e015d0>, \'Connection to ***.***.***.*** timed out. (connect timeout=60)\')\n\nDuring handling of the above exception, another exception occurred:\n\nTraceback (most recent call last):\n  File "/app/bazarr/bin/bazarr/../libs/requests/adapters.py", line 489, in send\n    resp = conn.urlopen(\n           ^^^^^^^^^^^^^\n  File "/app/bazarr/bin/bazarr/../libs/urllib3/connectionpool.py", line 787, in urlopen\n    retries = retries.increment(\n              ^^^^^^^^^^^^^^^^^^\n  File "/app/bazarr/bin/bazarr/../libs/urllib3/util/retry.py", line 592, in increment\n    raise MaxRetryError(_pool, url, error or ResponseError(cause))\nurllib3.exceptions.MaxRetryError: HTTPConnectionPool(host=\'***.***.***.***\', port=8989): Max retries exceeded with url: /api/v3/rootfolder?apikey=(removed) (Caused by ConnectTimeoutError(<urllib3.connection.HTTPConnection object at 0x7f1914e015d0>, \'Connection to ***.***.***.*** timed out. (connect timeout=60)\'))\n\nDuring handling of the above exception, another exception occurred:\n\nTraceback (most recent call last):\n  File "/app/bazarr/bin/bazarr/sonarr/rootfolder.py", line 22, in get_sonarr_rootfolder\n    rootfolder = requests.get(url_sonarr_api_rootfolder, timeout=int(settings.sonarr.http_timeout), verify=False, headers=headers)\n                 ^^^^^^^^^^^^^^^^^^^^^^^^^^^^^^^^^^^^^^^^^^^^^^^^^^^^^^^^^^^^^^^^^^^^^^^^^^^^^^^^^^^^^^^^^^^^^^^^^^^^^^^^^^^^^^^^^\n  File "/app/bazarr/bin/bazarr/../libs/requests/api.py", line 73, in get\n    return request("get", url, params=params, **kwargs)\n           ^^^^^^^^^^^^^^^^^^^^^^^^^^^^^^^^^^^^^^^^^^^^\n  File "/app/bazarr/bin/bazarr/../libs/requests/api.py", line 59, in request\n    return session.request(method=method, url=url, **kwargs)\n           ^^^^^^^^^^^^^^^^^^^^^^^^^^^^^^^^^^^^^^^^^^^^^^^^^\n  File "/app/bazarr/bin/bazarr/../libs/requests/sessions.py", line 587, in request\n    resp = self.send(prep, **send_kwargs)\n           ^^^^^^^^^^^^^^^^^^^^^^^^^^^^^^\n  File "/app/bazarr/bin/bazarr/../libs/requests/sessions.py", line 701, in send\n    r = adapter.send(request, **kwargs)\n        ^^^^^^^^^^^^^^^^^^^^^^^^^^^^^^^\n  File "/app/bazarr/bin/bazarr/../libs/requests/adapters.py", line 553, in send\n    raise ConnectTimeout(e, request=request)\nrequests.exceptions.ConnectTimeout: HTTPConnectionPool(host=\'***.***.***.***\', port=8989): Max retries exceeded with url: /api/v3/rootfolder?apikey=(removed) (Caused by ConnectTimeoutError(<urllib3.connection.HTTPConnection object at 0x7f1914e015d0>, \'Connection to ***.***.***.*** timed out. (connect timeout=60)\'))'|
06/01/2024 22:38:22|ERROR   |root                            |BAZARR Error trying to get tags from Sonarr. Connection Error.|'Traceback (most recent call last):\n  File "/app/bazarr/bin/bazarr/../libs/urllib3/connection.py", line 174, in _new_conn\n    conn = connection.create_connection(\n           ^^^^^^^^^^^^^^^^^^^^^^^^^^^^^\n  File "/app/bazarr/bin/bazarr/../libs/subliminal_patch/http.py", line 325, in patched_create_connection\n    return _orig_create_connection(address, *args, **kwargs)\n           ^^^^^^^^^^^^^^^^^^^^^^^^^^^^^^^^^^^^^^^^^^^^^^^^^\n  File "/app/bazarr/bin/bazarr/../libs/urllib3/util/connection.py", line 95, in create_connection\n    raise err\n  File "/app/bazarr/bin/bazarr/../libs/urllib3/util/connection.py", line 85, in create_connection\n    sock.connect(sa)\nTimeoutError: timed out\n\nDuring handling of the above exception, another exception occurred:\n\nTraceback (most recent call last):\n  File "/app/bazarr/bin/bazarr/../libs/urllib3/connectionpool.py", line 703, in urlopen\n    httplib_response = self._make_request(\n                       ^^^^^^^^^^^^^^^^^^^\n  File "/app/bazarr/bin/bazarr/../libs/urllib3/connectionpool.py", line 398, in _make_request\n    conn.request(method, url, **httplib_request_kw)\n  File "/app/bazarr/bin/bazarr/../libs/urllib3/connection.py", line 239, in request\n    super(HTTPConnection, self).request(method, url, body=body, headers=headers)\n  File "/usr/lib/python3.11/http/client.py", line 1286, in request\n    self._send_request(method, url, body, headers, encode_chunked)\n  File "/usr/lib/python3.11/http/client.py", line 1332, in _send_request\n    self.endheaders(body, encode_chunked=encode_chunked)\n  File "/usr/lib/python3.11/http/client.py", line 1281, in endheaders\n    self._send_output(message_body, encode_chunked=encode_chunked)\n  File "/usr/lib/python3.11/http/client.py", line 1041, in _send_output\n    self.send(msg)\n  File "/usr/lib/python3.11/http/client.py", line 979, in send\n    self.connect()\n  File "/app/bazarr/bin/bazarr/../libs/urllib3/connection.py", line 205, in connect\n    conn = self._new_conn()\n           ^^^^^^^^^^^^^^^^\n  File "/app/bazarr/bin/bazarr/../libs/urllib3/connection.py", line 179, in _new_conn\n    raise ConnectTimeoutError(\nurllib3.exceptions.ConnectTimeoutError: (<urllib3.connection.HTTPConnection object at 0x7f1914e2ab50>, \'Connection to ***.***.***.*** timed out. (connect timeout=60)\')\n\nDuring handling of the above exception, another exception occurred:\n\nTraceback (most recent call last):\n  File "/app/bazarr/bin/bazarr/../libs/requests/adapters.py", line 489, in send\n    resp = conn.urlopen(\n           ^^^^^^^^^^^^^\n  File "/app/bazarr/bin/bazarr/../libs/urllib3/connectionpool.py", line 787, in urlopen\n    retries = retries.increment(\n              ^^^^^^^^^^^^^^^^^^\n  File "/app/bazarr/bin/bazarr/../libs/urllib3/util/retry.py", line 592, in increment\n    raise MaxRetryError(_pool, url, error or ResponseError(cause))\nurllib3.exceptions.MaxRetryError: HTTPConnectionPool(host=\'***.***.***.***\', port=8989): Max retries exceeded with url: /api/v3/tag?apikey=(removed) (Caused by ConnectTimeoutError(<urllib3.connection.HTTPConnection object at 0x7f1914e2ab50>, \'Connection to ***.***.***.*** timed out. (connect timeout=60)\'))\n\nDuring handling of the above exception, another exception occurred:\n\nTraceback (most recent call last):\n  File "/app/bazarr/bin/bazarr/sonarr/sync/utils.py", line 56, in get_tags\n    tagsDict = requests.get(url_sonarr_api_series, timeout=int(settings.sonarr.http_timeout), verify=False, headers=headers)\n               ^^^^^^^^^^^^^^^^^^^^^^^^^^^^^^^^^^^^^^^^^^^^^^^^^^^^^^^^^^^^^^^^^^^^^^^^^^^^^^^^^^^^^^^^^^^^^^^^^^^^^^^^^^^^^\n  File "/app/bazarr/bin/bazarr/../libs/requests/api.py", line 73, in get\n    return request("get", url, params=params, **kwargs)\n           ^^^^^^^^^^^^^^^^^^^^^^^^^^^^^^^^^^^^^^^^^^^^\n  File "/app/bazarr/bin/bazarr/../libs/requests/api.py", line 59, in request\n    return session.request(method=method, url=url, **kwargs)\n           ^^^^^^^^^^^^^^^^^^^^^^^^^^^^^^^^^^^^^^^^^^^^^^^^^\n  File "/app/bazarr/bin/bazarr/../libs/requests/sessions.py", line 587, in request\n    resp = self.send(prep, **send_kwargs)\n           ^^^^^^^^^^^^^^^^^^^^^^^^^^^^^^\n  File "/app/bazarr/bin/bazarr/../libs/requests/sessions.py", line 701, in send\n    r = adapter.send(request, **kwargs)\n        ^^^^^^^^^^^^^^^^^^^^^^^^^^^^^^^\n  File "/app/bazarr/bin/bazarr/../libs/requests/adapters.py", line 553, in send\n    raise ConnectTimeout(e, request=request)\nrequests.exceptions.ConnectTimeout: HTTPConnectionPool(host=\'***.***.***.***\', port=8989): Max retries exceeded with url: /api/v3/tag?apikey=(removed) (Caused by ConnectTimeoutError(<urllib3.connection.HTTPConnection object at 0x7f1914e2ab50>, \'Connection to ***.***.***.*** timed out. (connect timeout=60)\'))'|
06/01/2024 22:40:22|ERROR   |root                            |BAZARR Error trying to get series from Sonarr. Connection Error.|'Traceback (most recent call last):\n  File "/app/bazarr/bin/bazarr/../libs/urllib3/connection.py", line 174, in _new_conn\n    conn = connection.create_connection(\n           ^^^^^^^^^^^^^^^^^^^^^^^^^^^^^\n  File "/app/bazarr/bin/bazarr/../libs/subliminal_patch/http.py", line 325, in patched_create_connection\n    return _orig_create_connection(address, *args, **kwargs)\n           ^^^^^^^^^^^^^^^^^^^^^^^^^^^^^^^^^^^^^^^^^^^^^^^^^\n  File "/app/bazarr/bin/bazarr/../libs/urllib3/util/connection.py", line 95, in create_connection\n    raise err\n  File "/app/bazarr/bin/bazarr/../libs/urllib3/util/connection.py", line 85, in create_connection\n    sock.connect(sa)\nTimeoutError: timed out\n\nDuring handling of the above exception, another exception occurred:\n\nTraceback (most recent call last):\n  File "/app/bazarr/bin/bazarr/../libs/urllib3/connectionpool.py", line 703, in urlopen\n    httplib_response = self._make_request(\n                       ^^^^^^^^^^^^^^^^^^^\n  File "/app/bazarr/bin/bazarr/../libs/urllib3/connectionpool.py", line 398, in _make_request\n    conn.request(method, url, **httplib_request_kw)\n  File "/app/bazarr/bin/bazarr/../libs/urllib3/connection.py", line 239, in request\n    super(HTTPConnection, self).request(method, url, body=body, headers=headers)\n  File "/usr/lib/python3.11/http/client.py", line 1286, in request\n    self._send_request(method, url, body, headers, encode_chunked)\n  File "/usr/lib/python3.11/http/client.py", line 1332, in _send_request\n    self.endheaders(body, encode_chunked=encode_chunked)\n  File "/usr/lib/python3.11/http/client.py", line 1281, in endheaders\n    self._send_output(message_body, encode_chunked=encode_chunked)\n  File "/usr/lib/python3.11/http/client.py", line 1041, in _send_output\n    self.send(msg)\n  File "/usr/lib/python3.11/http/client.py", line 979, in send\n    self.connect()\n  File "/app/bazarr/bin/bazarr/../libs/urllib3/connection.py", line 205, in connect\n    conn = self._new_conn()\n           ^^^^^^^^^^^^^^^^\n  File "/app/bazarr/bin/bazarr/../libs/urllib3/connection.py", line 179, in _new_conn\n    raise ConnectTimeoutError(\nurllib3.exceptions.ConnectTimeoutError: (<urllib3.connection.HTTPConnection object at 0x7f1914e33390>, \'Connection to ***.***.***.*** timed out. (connect timeout=60)\')\n\nDuring handling of the above exception, another exception occurred:\n\nTraceback (most recent call last):\n  File "/app/bazarr/bin/bazarr/../libs/requests/adapters.py", line 489, in send\n    resp = conn.urlopen(\n           ^^^^^^^^^^^^^\n  File "/app/bazarr/bin/bazarr/../libs/urllib3/connectionpool.py", line 787, in urlopen\n    retries = retries.increment(\n              ^^^^^^^^^^^^^^^^^^\n  File "/app/bazarr/bin/bazarr/../libs/urllib3/util/retry.py", line 592, in increment\n    raise MaxRetryError(_pool, url, error or ResponseError(cause))\nurllib3.exceptions.MaxRetryError: HTTPConnectionPool(host=\'***.***.***.***\', port=8989): Max retries exceeded with url: /api/v3/series/?apikey=(removed) (Caused by ConnectTimeoutError(<urllib3.connection.HTTPConnection object at 0x7f1914e33390>, \'Connection to ***.***.***.*** timed out. (connect timeout=60)\'))\n\nDuring handling of the above exception, another exception occurred:\n\nTraceback (most recent call last):\n  File "/app/bazarr/bin/bazarr/sonarr/sync/utils.py", line 74, in get_series_from_sonarr_api\n    r = requests.get(url_sonarr_api_series, timeout=int(settings.sonarr.http_timeout), verify=False, headers=headers)\n        ^^^^^^^^^^^^^^^^^^^^^^^^^^^^^^^^^^^^^^^^^^^^^^^^^^^^^^^^^^^^^^^^^^^^^^^^^^^^^^^^^^^^^^^^^^^^^^^^^^^^^^^^^^^^^\n  File "/app/bazarr/bin/bazarr/../libs/requests/api.py", line 73, in get\n    return request("get", url, params=params, **kwargs)\n           ^^^^^^^^^^^^^^^^^^^^^^^^^^^^^^^^^^^^^^^^^^^^\n  File "/app/bazarr/bin/bazarr/../libs/requests/api.py", line 59, in request\n    return session.request(method=method, url=url, **kwargs)\n           ^^^^^^^^^^^^^^^^^^^^^^^^^^^^^^^^^^^^^^^^^^^^^^^^^\n  File "/app/bazarr/bin/bazarr/../libs/requests/sessions.py", line 587, in request\n    resp = self.send(prep, **send_kwargs)\n           ^^^^^^^^^^^^^^^^^^^^^^^^^^^^^^\n  File "/app/bazarr/bin/bazarr/../libs/requests/sessions.py", line 701, in send\n    r = adapter.send(request, **kwargs)\n        ^^^^^^^^^^^^^^^^^^^^^^^^^^^^^^^\n  File "/app/bazarr/bin/bazarr/../libs/requests/adapters.py", line 553, in send\n    raise ConnectTimeout(e, request=request)\nrequests.exceptions.ConnectTimeout: HTTPConnectionPool(host=\'***.***.***.***\', port=8989): Max retries exceeded with url: /api/v3/series/?apikey=(removed) (Caused by ConnectTimeoutError(<urllib3.connection.HTTPConnection object at 0x7f1914e33390>, \'Connection to ***.***.***.*** timed out. (connect timeout=60)\'))'|
06/01/2024 22:51:21|ERROR   |root                            |BAZARR Error trying to get rootfolder from Sonarr. Connection Error.|'Traceback (most recent call last):\n  File "/app/bazarr/bin/bazarr/../libs/urllib3/connection.py", line 174, in _new_conn\n    conn = connection.create_connection(\n           ^^^^^^^^^^^^^^^^^^^^^^^^^^^^^\n  File "/app/bazarr/bin/bazarr/../libs/subliminal_patch/http.py", line 325, in patched_create_connection\n    return _orig_create_connection(address, *args, **kwargs)\n           ^^^^^^^^^^^^^^^^^^^^^^^^^^^^^^^^^^^^^^^^^^^^^^^^^\n  File "/app/bazarr/bin/bazarr/../libs/urllib3/util/connection.py", line 95, in create_connection\n    raise err\n  File "/app/bazarr/bin/bazarr/../libs/urllib3/util/connection.py", line 85, in create_connection\n    sock.connect(sa)\nTimeoutError: timed out\n\nDuring handling of the above exception, another exception occurred:\n\nTraceback (most recent call last):\n  File "/app/bazarr/bin/bazarr/../libs/urllib3/connectionpool.py", line 703, in urlopen\n    httplib_response = self._make_request(\n                       ^^^^^^^^^^^^^^^^^^^\n  File "/app/bazarr/bin/bazarr/../libs/urllib3/connectionpool.py", line 398, in _make_request\n    conn.request(method, url, **httplib_request_kw)\n  File "/app/bazarr/bin/bazarr/../libs/urllib3/connection.py", line 239, in request\n    super(HTTPConnection, self).request(method, url, body=body, headers=headers)\n  File "/usr/lib/python3.11/http/client.py", line 1286, in request\n    self._send_request(method, url, body, headers, encode_chunked)\n  File "/usr/lib/python3.11/http/client.py", line 1332, in _send_request\n    self.endheaders(body, encode_chunked=encode_chunked)\n  File "/usr/lib/python3.11/http/client.py", line 1281, in endheaders\n    self._send_output(message_body, encode_chunked=encode_chunked)\n  File "/usr/lib/python3.11/http/client.py", line 1041, in _send_output\n    self.send(msg)\n  File "/usr/lib/python3.11/http/client.py", line 979, in send\n    self.connect()\n  File "/app/bazarr/bin/bazarr/../libs/urllib3/connection.py", line 205, in connect\n    conn = self._new_conn()\n           ^^^^^^^^^^^^^^^^\n  File "/app/bazarr/bin/bazarr/../libs/urllib3/connection.py", line 179, in _new_conn\n    raise ConnectTimeoutError(\nurllib3.exceptions.ConnectTimeoutError: (<urllib3.connection.HTTPConnection object at 0x7f1914e45510>, \'Connection to ***.***.***.*** timed out. (connect timeout=60)\')\n\nDuring handling of the above exception, another exception occurred:\n\nTraceback (most recent call last):\n  File "/app/bazarr/bin/bazarr/../libs/requests/adapters.py", line 489, in send\n    resp = conn.urlopen(\n           ^^^^^^^^^^^^^\n  File "/app/bazarr/bin/bazarr/../libs/urllib3/connectionpool.py", line 787, in urlopen\n    retries = retries.increment(\n              ^^^^^^^^^^^^^^^^^^\n  File "/app/bazarr/bin/bazarr/../libs/urllib3/util/retry.py", line 592, in increment\n    raise MaxRetryError(_pool, url, error or ResponseError(cause))\nurllib3.exceptions.MaxRetryError: HTTPConnectionPool(host=\'***.***.***.***\', port=8989): Max retries exceeded with url: /api/v3/rootfolder?apikey=(removed) (Caused by ConnectTimeoutError(<urllib3.connection.HTTPConnection object at 0x7f1914e45510>, \'Connection to ***.***.***.*** timed out. (connect timeout=60)\'))\n\nDuring handling of the above exception, another exception occurred:\n\nTraceback (most recent call last):\n  File "/app/bazarr/bin/bazarr/sonarr/rootfolder.py", line 22, in get_sonarr_rootfolder\n    rootfolder = requests.get(url_sonarr_api_rootfolder, timeout=int(settings.sonarr.http_timeout), verify=False, headers=headers)\n                 ^^^^^^^^^^^^^^^^^^^^^^^^^^^^^^^^^^^^^^^^^^^^^^^^^^^^^^^^^^^^^^^^^^^^^^^^^^^^^^^^^^^^^^^^^^^^^^^^^^^^^^^^^^^^^^^^^\n  File "/app/bazarr/bin/bazarr/../libs/requests/api.py", line 73, in get\n    return request("get", url, params=params, **kwargs)\n           ^^^^^^^^^^^^^^^^^^^^^^^^^^^^^^^^^^^^^^^^^^^^\n  File "/app/bazarr/bin/bazarr/../libs/requests/api.py", line 59, in request\n    return session.request(method=method, url=url, **kwargs)\n           ^^^^^^^^^^^^^^^^^^^^^^^^^^^^^^^^^^^^^^^^^^^^^^^^^\n  File "/app/bazarr/bin/bazarr/../libs/requests/sessions.py", line 587, in request\n    resp = self.send(prep, **send_kwargs)\n           ^^^^^^^^^^^^^^^^^^^^^^^^^^^^^^\n  File "/app/bazarr/bin/bazarr/../libs/requests/sessions.py", line 701, in send\n    r = adapter.send(request, **kwargs)\n        ^^^^^^^^^^^^^^^^^^^^^^^^^^^^^^^\n  File "/app/bazarr/bin/bazarr/../libs/requests/adapters.py", line 553, in send\n    raise ConnectTimeout(e, request=request)\nrequests.exceptions.ConnectTimeout: HTTPConnectionPool(host=\'***.***.***.***\', port=8989): Max retries exceeded with url: /api/v3/rootfolder?apikey=(removed) (Caused by ConnectTimeoutError(<urllib3.connection.HTTPConnection object at 0x7f1914e45510>, \'Connection to ***.***.***.*** timed out. (connect timeout=60)\'))'|
06/01/2024 22:53:22|ERROR   |root                            |BAZARR Error trying to get tags from Sonarr. Connection Error.|'Traceback (most recent call last):\n  File "/app/bazarr/bin/bazarr/../libs/urllib3/connection.py", line 174, in _new_conn\n    conn = connection.create_connection(\n           ^^^^^^^^^^^^^^^^^^^^^^^^^^^^^\n  File "/app/bazarr/bin/bazarr/../libs/subliminal_patch/http.py", line 325, in patched_create_connection\n    return _orig_create_connection(address, *args, **kwargs)\n           ^^^^^^^^^^^^^^^^^^^^^^^^^^^^^^^^^^^^^^^^^^^^^^^^^\n  File "/app/bazarr/bin/bazarr/../libs/urllib3/util/connection.py", line 95, in create_connection\n    raise err\n  File "/app/bazarr/bin/bazarr/../libs/urllib3/util/connection.py", line 85, in create_connection\n    sock.connect(sa)\nTimeoutError: timed out\n\nDuring handling of the above exception, another exception occurred:\n\nTraceback (most recent call last):\n  File "/app/bazarr/bin/bazarr/../libs/urllib3/connectionpool.py", line 703, in urlopen\n    httplib_response = self._make_request(\n                       ^^^^^^^^^^^^^^^^^^^\n  File "/app/bazarr/bin/bazarr/../libs/urllib3/connectionpool.py", line 398, in _make_request\n    conn.request(method, url, **httplib_request_kw)\n  File "/app/bazarr/bin/bazarr/../libs/urllib3/connection.py", line 239, in request\n    super(HTTPConnection, self).request(method, url, body=body, headers=headers)\n  File "/usr/lib/python3.11/http/client.py", line 1286, in request\n    self._send_request(method, url, body, headers, encode_chunked)\n  File "/usr/lib/python3.11/http/client.py", line 1332, in _send_request\n    self.endheaders(body, encode_chunked=encode_chunked)\n  File "/usr/lib/python3.11/http/client.py", line 1281, in endheaders\n    self._send_output(message_body, encode_chunked=encode_chunked)\n  File "/usr/lib/python3.11/http/client.py", line 1041, in _send_output\n    self.send(msg)\n  File "/usr/lib/python3.11/http/client.py", line 979, in send\n    self.connect()\n  File "/app/bazarr/bin/bazarr/../libs/urllib3/connection.py", line 205, in connect\n    conn = self._new_conn()\n           ^^^^^^^^^^^^^^^^\n  File "/app/bazarr/bin/bazarr/../libs/urllib3/connection.py", line 179, in _new_conn\n    raise ConnectTimeoutError(\nurllib3.exceptions.ConnectTimeoutError: (<urllib3.connection.HTTPConnection object at 0x7f1922dde510>, \'Connection to ***.***.***.*** timed out. (connect timeout=60)\')\n\nDuring handling of the above exception, another exception occurred:\n\nTraceback (most recent call last):\n  File "/app/bazarr/bin/bazarr/../libs/requests/adapters.py", line 489, in send\n    resp = conn.urlopen(\n           ^^^^^^^^^^^^^\n  File "/app/bazarr/bin/bazarr/../libs/urllib3/connectionpool.py", line 787, in urlopen\n    retries = retries.increment(\n              ^^^^^^^^^^^^^^^^^^\n  File "/app/bazarr/bin/bazarr/../libs/urllib3/util/retry.py", line 592, in increment\n    raise MaxRetryError(_pool, url, error or ResponseError(cause))\nurllib3.exceptions.MaxRetryError: HTTPConnectionPool(host=\'***.***.***.***\', port=8989): Max retries exceeded with url: /api/v3/tag?apikey=(removed) (Caused by ConnectTimeoutError(<urllib3.connection.HTTPConnection object at 0x7f1922dde510>, \'Connection to ***.***.***.*** timed out. (connect timeout=60)\'))\n\nDuring handling of the above exception, another exception occurred:\n\nTraceback (most recent call last):\n  File "/app/bazarr/bin/bazarr/sonarr/sync/utils.py", line 56, in get_tags\n    tagsDict = requests.get(url_sonarr_api_series, timeout=int(settings.sonarr.http_timeout), verify=False, headers=headers)\n               ^^^^^^^^^^^^^^^^^^^^^^^^^^^^^^^^^^^^^^^^^^^^^^^^^^^^^^^^^^^^^^^^^^^^^^^^^^^^^^^^^^^^^^^^^^^^^^^^^^^^^^^^^^^^^\n  File "/app/bazarr/bin/bazarr/../libs/requests/api.py", line 73, in get\n    return request("get", url, params=params, **kwargs)\n           ^^^^^^^^^^^^^^^^^^^^^^^^^^^^^^^^^^^^^^^^^^^^\n  File "/app/bazarr/bin/bazarr/../libs/requests/api.py", line 59, in request\n    return session.request(method=method, url=url, **kwargs)\n           ^^^^^^^^^^^^^^^^^^^^^^^^^^^^^^^^^^^^^^^^^^^^^^^^^\n  File "/app/bazarr/bin/bazarr/../libs/requests/sessions.py", line 587, in request\n    resp = self.send(prep, **send_kwargs)\n           ^^^^^^^^^^^^^^^^^^^^^^^^^^^^^^\n  File "/app/bazarr/bin/bazarr/../libs/requests/sessions.py", line 701, in send\n    r = adapter.send(request, **kwargs)\n        ^^^^^^^^^^^^^^^^^^^^^^^^^^^^^^^\n  File "/app/bazarr/bin/bazarr/../libs/requests/adapters.py", line 553, in send\n    raise ConnectTimeout(e, request=request)\nrequests.exceptions.ConnectTimeout: HTTPConnectionPool(host=\'***.***.***.***\', port=8989): Max retries exceeded with url: /api/v3/tag?apikey=(removed) (Caused by ConnectTimeoutError(<urllib3.connection.HTTPConnection object at 0x7f1922dde510>, \'Connection to ***.***.***.*** timed out. (connect timeout=60)\'))'|
06/01/2024 22:55:22|ERROR   |root                            |BAZARR Error trying to get series from Sonarr. Connection Error.|'Traceback (most recent call last):\n  File "/app/bazarr/bin/bazarr/../libs/urllib3/connection.py", line 174, in _new_conn\n    conn = connection.create_connection(\n           ^^^^^^^^^^^^^^^^^^^^^^^^^^^^^\n  File "/app/bazarr/bin/bazarr/../libs/subliminal_patch/http.py", line 325, in patched_create_connection\n    return _orig_create_connection(address, *args, **kwargs)\n           ^^^^^^^^^^^^^^^^^^^^^^^^^^^^^^^^^^^^^^^^^^^^^^^^^\n  File "/app/bazarr/bin/bazarr/../libs/urllib3/util/connection.py", line 95, in create_connection\n    raise err\n  File "/app/bazarr/bin/bazarr/../libs/urllib3/util/connection.py", line 85, in create_connection\n    sock.connect(sa)\nTimeoutError: timed out\n\nDuring handling of the above exception, another exception occurred:\n\nTraceback (most recent call last):\n  File "/app/bazarr/bin/bazarr/../libs/urllib3/connectionpool.py", line 703, in urlopen\n    httplib_response = self._make_request(\n                       ^^^^^^^^^^^^^^^^^^^\n  File "/app/bazarr/bin/bazarr/../libs/urllib3/connectionpool.py", line 398, in _make_request\n    conn.request(method, url, **httplib_request_kw)\n  File "/app/bazarr/bin/bazarr/../libs/urllib3/connection.py", line 239, in request\n    super(HTTPConnection, self).request(method, url, body=body, headers=headers)\n  File "/usr/lib/python3.11/http/client.py", line 1286, in request\n    self._send_request(method, url, body, headers, encode_chunked)\n  File "/usr/lib/python3.11/http/client.py", line 1332, in _send_request\n    self.endheaders(body, encode_chunked=encode_chunked)\n  File "/usr/lib/python3.11/http/client.py", line 1281, in endheaders\n    self._send_output(message_body, encode_chunked=encode_chunked)\n  File "/usr/lib/python3.11/http/client.py", line 1041, in _send_output\n    self.send(msg)\n  File "/usr/lib/python3.11/http/client.py", line 979, in send\n    self.connect()\n  File "/app/bazarr/bin/bazarr/../libs/urllib3/connection.py", line 205, in connect\n    conn = self._new_conn()\n           ^^^^^^^^^^^^^^^^\n  File "/app/bazarr/bin/bazarr/../libs/urllib3/connection.py", line 179, in _new_conn\n    raise ConnectTimeoutError(\nurllib3.exceptions.ConnectTimeoutError: (<urllib3.connection.HTTPConnection object at 0x7f1922de6010>, \'Connection to ***.***.***.*** timed out. (connect timeout=60)\')\n\nDuring handling of the above exception, another exception occurred:\n\nTraceback (most recent call last):\n  File "/app/bazarr/bin/bazarr/../libs/requests/adapters.py", line 489, in send\n    resp = conn.urlopen(\n           ^^^^^^^^^^^^^\n  File "/app/bazarr/bin/bazarr/../libs/urllib3/connectionpool.py", line 787, in urlopen\n    retries = retries.increment(\n              ^^^^^^^^^^^^^^^^^^\n  File "/app/bazarr/bin/bazarr/../libs/urllib3/util/retry.py", line 592, in increment\n    raise MaxRetryError(_pool, url, error or ResponseError(cause))\nurllib3.exceptions.MaxRetryError: HTTPConnectionPool(host=\'***.***.***.***\', port=8989): Max retries exceeded with url: /api/v3/series/?apikey=(removed) (Caused by ConnectTimeoutError(<urllib3.connection.HTTPConnection object at 0x7f1922de6010>, \'Connection to ***.***.***.*** timed out. (connect timeout=60)\'))\n\nDuring handling of the above exception, another exception occurred:\n\nTraceback (most recent call last):\n  File "/app/bazarr/bin/bazarr/sonarr/sync/utils.py", line 74, in get_series_from_sonarr_api\n    r = requests.get(url_sonarr_api_series, timeout=int(settings.sonarr.http_timeout), verify=False, headers=headers)\n        ^^^^^^^^^^^^^^^^^^^^^^^^^^^^^^^^^^^^^^^^^^^^^^^^^^^^^^^^^^^^^^^^^^^^^^^^^^^^^^^^^^^^^^^^^^^^^^^^^^^^^^^^^^^^^\n  File "/app/bazarr/bin/bazarr/../libs/requests/api.py", line 73, in get\n    return request("get", url, params=params, **kwargs)\n           ^^^^^^^^^^^^^^^^^^^^^^^^^^^^^^^^^^^^^^^^^^^^\n  File "/app/bazarr/bin/bazarr/../libs/requests/api.py", line 59, in request\n    return session.request(method=method, url=url, **kwargs)\n           ^^^^^^^^^^^^^^^^^^^^^^^^^^^^^^^^^^^^^^^^^^^^^^^^^\n  File "/app/bazarr/bin/bazarr/../libs/requests/sessions.py", line 587, in request\n    resp = self.send(prep, **send_kwargs)\n           ^^^^^^^^^^^^^^^^^^^^^^^^^^^^^^\n  File "/app/bazarr/bin/bazarr/../libs/requests/sessions.py", line 701, in send\n    r = adapter.send(request, **kwargs)\n        ^^^^^^^^^^^^^^^^^^^^^^^^^^^^^^^\n  File "/app/bazarr/bin/bazarr/../libs/requests/adapters.py", line 553, in send\n    raise ConnectTimeout(e, request=request)\nrequests.exceptions.ConnectTimeout: HTTPConnectionPool(host=\'***.***.***.***\', port=8989): Max retries exceeded with url: /api/v3/series/?apikey=(removed) (Caused by ConnectTimeoutError(<urllib3.connection.HTTPConnection object at 0x7f1922de6010>, \'Connection to ***.***.***.*** timed out. (connect timeout=60)\'))'|
06/01/2024 23:06:22|ERROR   |root                            |BAZARR Error trying to get rootfolder from Sonarr. Connection Error.|'Traceback (most recent call last):\n  File "/app/bazarr/bin/bazarr/../libs/urllib3/connection.py", line 174, in _new_conn\n    conn = connection.create_connection(\n           ^^^^^^^^^^^^^^^^^^^^^^^^^^^^^\n  File "/app/bazarr/bin/bazarr/../libs/subliminal_patch/http.py", line 325, in patched_create_connection\n    return _orig_create_connection(address, *args, **kwargs)\n           ^^^^^^^^^^^^^^^^^^^^^^^^^^^^^^^^^^^^^^^^^^^^^^^^^\n  File "/app/bazarr/bin/bazarr/../libs/urllib3/util/connection.py", line 95, in create_connection\n    raise err\n  File "/app/bazarr/bin/bazarr/../libs/urllib3/util/connection.py", line 85, in create_connection\n    sock.connect(sa)\nTimeoutError: timed out\n\nDuring handling of the above exception, another exception occurred:\n\nTraceback (most recent call last):\n  File "/app/bazarr/bin/bazarr/../libs/urllib3/connectionpool.py", line 703, in urlopen\n    httplib_response = self._make_request(\n                       ^^^^^^^^^^^^^^^^^^^\n  File "/app/bazarr/bin/bazarr/../libs/urllib3/connectionpool.py", line 398, in _make_request\n    conn.request(method, url, **httplib_request_kw)\n  File "/app/bazarr/bin/bazarr/../libs/urllib3/connection.py", line 239, in request\n    super(HTTPConnection, self).request(method, url, body=body, headers=headers)\n  File "/usr/lib/python3.11/http/client.py", line 1286, in request\n    self._send_request(method, url, body, headers, encode_chunked)\n  File "/usr/lib/python3.11/http/client.py", line 1332, in _send_request\n    self.endheaders(body, encode_chunked=encode_chunked)\n  File "/usr/lib/python3.11/http/client.py", line 1281, in endheaders\n    self._send_output(message_body, encode_chunked=encode_chunked)\n  File "/usr/lib/python3.11/http/client.py", line 1041, in _send_output\n    self.send(msg)\n  File "/usr/lib/python3.11/http/client.py", line 979, in send\n    self.connect()\n  File "/app/bazarr/bin/bazarr/../libs/urllib3/connection.py", line 205, in connect\n    conn = self._new_conn()\n           ^^^^^^^^^^^^^^^^\n  File "/app/bazarr/bin/bazarr/../libs/urllib3/connection.py", line 179, in _new_conn\n    raise ConnectTimeoutError(\nurllib3.exceptions.ConnectTimeoutError: (<urllib3.connection.HTTPConnection object at 0x7f1915464cd0>, \'Connection to ***.***.***.*** timed out. (connect timeout=60)\')\n\nDuring handling of the above exception, another exception occurred:\n\nTraceback (most recent call last):\n  File "/app/bazarr/bin/bazarr/../libs/requests/adapters.py", line 489, in send\n    resp = conn.urlopen(\n           ^^^^^^^^^^^^^\n  File "/app/bazarr/bin/bazarr/../libs/urllib3/connectionpool.py", line 787, in urlopen\n    retries = retries.increment(\n              ^^^^^^^^^^^^^^^^^^\n  File "/app/bazarr/bin/bazarr/../libs/urllib3/util/retry.py", line 592, in increment\n    raise MaxRetryError(_pool, url, error or ResponseError(cause))\nurllib3.exceptions.MaxRetryError: HTTPConnectionPool(host=\'***.***.***.***\', port=8989): Max retries exceeded with url: /api/v3/rootfolder?apikey=(removed) (Caused by ConnectTimeoutError(<urllib3.connection.HTTPConnection object at 0x7f1915464cd0>, \'Connection to ***.***.***.*** timed out. (connect timeout=60)\'))\n\nDuring handling of the above exception, another exception occurred:\n\nTraceback (most recent call last):\n  File "/app/bazarr/bin/bazarr/sonarr/rootfolder.py", line 22, in get_sonarr_rootfolder\n    rootfolder = requests.get(url_sonarr_api_rootfolder, timeout=int(settings.sonarr.http_timeout), verify=False, headers=headers)\n                 ^^^^^^^^^^^^^^^^^^^^^^^^^^^^^^^^^^^^^^^^^^^^^^^^^^^^^^^^^^^^^^^^^^^^^^^^^^^^^^^^^^^^^^^^^^^^^^^^^^^^^^^^^^^^^^^^^\n  File "/app/bazarr/bin/bazarr/../libs/requests/api.py", line 73, in get\n    return request("get", url, params=params, **kwargs)\n           ^^^^^^^^^^^^^^^^^^^^^^^^^^^^^^^^^^^^^^^^^^^^\n  File "/app/bazarr/bin/bazarr/../libs/requests/api.py", line 59, in request\n    return session.request(method=method, url=url, **kwargs)\n           ^^^^^^^^^^^^^^^^^^^^^^^^^^^^^^^^^^^^^^^^^^^^^^^^^\n  File "/app/bazarr/bin/bazarr/../libs/requests/sessions.py", line 587, in request\n    resp = self.send(prep, **send_kwargs)\n           ^^^^^^^^^^^^^^^^^^^^^^^^^^^^^^\n  File "/app/bazarr/bin/bazarr/../libs/requests/sessions.py", line 701, in send\n    r = adapter.send(request, **kwargs)\n        ^^^^^^^^^^^^^^^^^^^^^^^^^^^^^^^\n  File "/app/bazarr/bin/bazarr/../libs/requests/adapters.py", line 553, in send\n    raise ConnectTimeout(e, request=request)\nrequests.exceptions.ConnectTimeout: HTTPConnectionPool(host=\'***.***.***.***\', port=8989): Max retries exceeded with url: /api/v3/rootfolder?apikey=(removed) (Caused by ConnectTimeoutError(<urllib3.connection.HTTPConnection object at 0x7f1915464cd0>, \'Connection to ***.***.***.*** timed out. (connect timeout=60)\'))'|
06/01/2024 23:08:22|ERROR   |root                            |BAZARR Error trying to get tags from Sonarr. Connection Error.|'Traceback (most recent call last):\n  File "/app/bazarr/bin/bazarr/../libs/urllib3/connection.py", line 174, in _new_conn\n    conn = connection.create_connection(\n           ^^^^^^^^^^^^^^^^^^^^^^^^^^^^^\n  File "/app/bazarr/bin/bazarr/../libs/subliminal_patch/http.py", line 325, in patched_create_connection\n    return _orig_create_connection(address, *args, **kwargs)\n           ^^^^^^^^^^^^^^^^^^^^^^^^^^^^^^^^^^^^^^^^^^^^^^^^^\n  File "/app/bazarr/bin/bazarr/../libs/urllib3/util/connection.py", line 95, in create_connection\n    raise err\n  File "/app/bazarr/bin/bazarr/../libs/urllib3/util/connection.py", line 85, in create_connection\n    sock.connect(sa)\nTimeoutError: timed out\n\nDuring handling of the above exception, another exception occurred:\n\nTraceback (most recent call last):\n  File "/app/bazarr/bin/bazarr/../libs/urllib3/connectionpool.py", line 703, in urlopen\n    httplib_response = self._make_request(\n                       ^^^^^^^^^^^^^^^^^^^\n  File "/app/bazarr/bin/bazarr/../libs/urllib3/connectionpool.py", line 398, in _make_request\n    conn.request(method, url, **httplib_request_kw)\n  File "/app/bazarr/bin/bazarr/../libs/urllib3/connection.py", line 239, in request\n    super(HTTPConnection, self).request(method, url, body=body, headers=headers)\n  File "/usr/lib/python3.11/http/client.py", line 1286, in request\n    self._send_request(method, url, body, headers, encode_chunked)\n  File "/usr/lib/python3.11/http/client.py", line 1332, in _send_request\n    self.endheaders(body, encode_chunked=encode_chunked)\n  File "/usr/lib/python3.11/http/client.py", line 1281, in endheaders\n    self._send_output(message_body, encode_chunked=encode_chunked)\n  File "/usr/lib/python3.11/http/client.py", line 1041, in _send_output\n    self.send(msg)\n  File "/usr/lib/python3.11/http/client.py", line 979, in send\n    self.connect()\n  File "/app/bazarr/bin/bazarr/../libs/urllib3/connection.py", line 205, in connect\n    conn = self._new_conn()\n           ^^^^^^^^^^^^^^^^\n  File "/app/bazarr/bin/bazarr/../libs/urllib3/connection.py", line 179, in _new_conn\n    raise ConnectTimeoutError(\nurllib3.exceptions.ConnectTimeoutError: (<urllib3.connection.HTTPConnection object at 0x7f1922de5ad0>, \'Connection to ***.***.***.*** timed out. (connect timeout=60)\')\n\nDuring handling of the above exception, another exception occurred:\n\nTraceback (most recent call last):\n  File "/app/bazarr/bin/bazarr/../libs/requests/adapters.py", line 489, in send\n    resp = conn.urlopen(\n           ^^^^^^^^^^^^^\n  File "/app/bazarr/bin/bazarr/../libs/urllib3/connectionpool.py", line 787, in urlopen\n    retries = retries.increment(\n              ^^^^^^^^^^^^^^^^^^\n  File "/app/bazarr/bin/bazarr/../libs/urllib3/util/retry.py", line 592, in increment\n    raise MaxRetryError(_pool, url, error or ResponseError(cause))\nurllib3.exceptions.MaxRetryError: HTTPConnectionPool(host=\'***.***.***.***\', port=8989): Max retries exceeded with url: /api/v3/tag?apikey=(removed) (Caused by ConnectTimeoutError(<urllib3.connection.HTTPConnection object at 0x7f1922de5ad0>, \'Connection to ***.***.***.*** timed out. (connect timeout=60)\'))\n\nDuring handling of the above exception, another exception occurred:\n\nTraceback (most recent call last):\n  File "/app/bazarr/bin/bazarr/sonarr/sync/utils.py", line 56, in get_tags\n    tagsDict = requests.get(url_sonarr_api_series, timeout=int(settings.sonarr.http_timeout), verify=False, headers=headers)\n               ^^^^^^^^^^^^^^^^^^^^^^^^^^^^^^^^^^^^^^^^^^^^^^^^^^^^^^^^^^^^^^^^^^^^^^^^^^^^^^^^^^^^^^^^^^^^^^^^^^^^^^^^^^^^^\n  File "/app/bazarr/bin/bazarr/../libs/requests/api.py", line 73, in get\n    return request("get", url, params=params, **kwargs)\n           ^^^^^^^^^^^^^^^^^^^^^^^^^^^^^^^^^^^^^^^^^^^^\n  File "/app/bazarr/bin/bazarr/../libs/requests/api.py", line 59, in request\n    return session.request(method=method, url=url, **kwargs)\n           ^^^^^^^^^^^^^^^^^^^^^^^^^^^^^^^^^^^^^^^^^^^^^^^^^\n  File "/app/bazarr/bin/bazarr/../libs/requests/sessions.py", line 587, in request\n    resp = self.send(prep, **send_kwargs)\n           ^^^^^^^^^^^^^^^^^^^^^^^^^^^^^^\n  File "/app/bazarr/bin/bazarr/../libs/requests/sessions.py", line 701, in send\n    r = adapter.send(request, **kwargs)\n        ^^^^^^^^^^^^^^^^^^^^^^^^^^^^^^^\n  File "/app/bazarr/bin/bazarr/../libs/requests/adapters.py", line 553, in send\n    raise ConnectTimeout(e, request=request)\nrequests.exceptions.ConnectTimeout: HTTPConnectionPool(host=\'***.***.***.***\', port=8989): Max retries exceeded with url: /api/v3/tag?apikey=(removed) (Caused by ConnectTimeoutError(<urllib3.connection.HTTPConnection object at 0x7f1922de5ad0>, \'Connection to ***.***.***.*** timed out. (connect timeout=60)\'))'|
06/01/2024 23:10:22|ERROR   |root                            |BAZARR Error trying to get series from Sonarr. Connection Error.|'Traceback (most recent call last):\n  File "/app/bazarr/bin/bazarr/../libs/urllib3/connection.py", line 174, in _new_conn\n    conn = connection.create_connection(\n           ^^^^^^^^^^^^^^^^^^^^^^^^^^^^^\n  File "/app/bazarr/bin/bazarr/../libs/subliminal_patch/http.py", line 325, in patched_create_connection\n    return _orig_create_connection(address, *args, **kwargs)\n           ^^^^^^^^^^^^^^^^^^^^^^^^^^^^^^^^^^^^^^^^^^^^^^^^^\n  File "/app/bazarr/bin/bazarr/../libs/urllib3/util/connection.py", line 95, in create_connection\n    raise err\n  File "/app/bazarr/bin/bazarr/../libs/urllib3/util/connection.py", line 85, in create_connection\n    sock.connect(sa)\nTimeoutError: timed out\n\nDuring handling of the above exception, another exception occurred:\n\nTraceback (most recent call last):\n  File "/app/bazarr/bin/bazarr/../libs/urllib3/connectionpool.py", line 703, in urlopen\n    httplib_response = self._make_request(\n                       ^^^^^^^^^^^^^^^^^^^\n  File "/app/bazarr/bin/bazarr/../libs/urllib3/connectionpool.py", line 398, in _make_request\n    conn.request(method, url, **httplib_request_kw)\n  File "/app/bazarr/bin/bazarr/../libs/urllib3/connection.py", line 239, in request\n    super(HTTPConnection, self).request(method, url, body=body, headers=headers)\n  File "/usr/lib/python3.11/http/client.py", line 1286, in request\n    self._send_request(method, url, body, headers, encode_chunked)\n  File "/usr/lib/python3.11/http/client.py", line 1332, in _send_request\n    self.endheaders(body, encode_chunked=encode_chunked)\n  File "/usr/lib/python3.11/http/client.py", line 1281, in endheaders\n    self._send_output(message_body, encode_chunked=encode_chunked)\n  File "/usr/lib/python3.11/http/client.py", line 1041, in _send_output\n    self.send(msg)\n  File "/usr/lib/python3.11/http/client.py", line 979, in send\n    self.connect()\n  File "/app/bazarr/bin/bazarr/../libs/urllib3/connection.py", line 205, in connect\n    conn = self._new_conn()\n           ^^^^^^^^^^^^^^^^\n  File "/app/bazarr/bin/bazarr/../libs/urllib3/connection.py", line 179, in _new_conn\n    raise ConnectTimeoutError(\nurllib3.exceptions.ConnectTimeoutError: (<urllib3.connection.HTTPConnection object at 0x7f1914eb0790>, \'Connection to ***.***.***.*** timed out. (connect timeout=60)\')\n\nDuring handling of the above exception, another exception occurred:\n\nTraceback (most recent call last):\n  File "/app/bazarr/bin/bazarr/../libs/requests/adapters.py", line 489, in send\n    resp = conn.urlopen(\n           ^^^^^^^^^^^^^\n  File "/app/bazarr/bin/bazarr/../libs/urllib3/connectionpool.py", line 787, in urlopen\n    retries = retries.increment(\n              ^^^^^^^^^^^^^^^^^^\n  File "/app/bazarr/bin/bazarr/../libs/urllib3/util/retry.py", line 592, in increment\n    raise MaxRetryError(_pool, url, error or ResponseError(cause))\nurllib3.exceptions.MaxRetryError: HTTPConnectionPool(host=\'***.***.***.***\', port=8989): Max retries exceeded with url: /api/v3/series/?apikey=(removed) (Caused by ConnectTimeoutError(<urllib3.connection.HTTPConnection object at 0x7f1914eb0790>, \'Connection to ***.***.***.*** timed out. (connect timeout=60)\'))\n\nDuring handling of the above exception, another exception occurred:\n\nTraceback (most recent call last):\n  File "/app/bazarr/bin/bazarr/sonarr/sync/utils.py", line 74, in get_series_from_sonarr_api\n    r = requests.get(url_sonarr_api_series, timeout=int(settings.sonarr.http_timeout), verify=False, headers=headers)\n        ^^^^^^^^^^^^^^^^^^^^^^^^^^^^^^^^^^^^^^^^^^^^^^^^^^^^^^^^^^^^^^^^^^^^^^^^^^^^^^^^^^^^^^^^^^^^^^^^^^^^^^^^^^^^^\n  File "/app/bazarr/bin/bazarr/../libs/requests/api.py", line 73, in get\n    return request("get", url, params=params, **kwargs)\n           ^^^^^^^^^^^^^^^^^^^^^^^^^^^^^^^^^^^^^^^^^^^^\n  File "/app/bazarr/bin/bazarr/../libs/requests/api.py", line 59, in request\n    return session.request(method=method, url=url, **kwargs)\n           ^^^^^^^^^^^^^^^^^^^^^^^^^^^^^^^^^^^^^^^^^^^^^^^^^\n  File "/app/bazarr/bin/bazarr/../libs/requests/sessions.py", line 587, in request\n    resp = self.send(prep, **send_kwargs)\n           ^^^^^^^^^^^^^^^^^^^^^^^^^^^^^^\n  File "/app/bazarr/bin/bazarr/../libs/requests/sessions.py", line 701, in send\n    r = adapter.send(request, **kwargs)\n        ^^^^^^^^^^^^^^^^^^^^^^^^^^^^^^^\n  File "/app/bazarr/bin/bazarr/../libs/requests/adapters.py", line 553, in send\n    raise ConnectTimeout(e, request=request)\nrequests.exceptions.ConnectTimeout: HTTPConnectionPool(host=\'***.***.***.***\', port=8989): Max retries exceeded with url: /api/v3/series/?apikey=(removed) (Caused by ConnectTimeoutError(<urllib3.connection.HTTPConnection object at 0x7f1914eb0790>, \'Connection to ***.***.***.*** timed out. (connect timeout=60)\'))'|
06/01/2024 23:28:00|INFO    |root                            |BAZARR trying to connect to Sonarr SignalR feed...|
06/01/2024 23:28:00|INFO    |root                            |BAZARR trying to connect to Radarr SignalR feed...|
06/01/2024 23:28:00|INFO    |root                            |BAZARR is started and waiting for request on http://***.***.***.***:6767|
06/01/2024 23:31:51|INFO    |root                            |BAZARR trying to connect to Sonarr SignalR feed...|
06/01/2024 23:31:51|INFO    |root                            |BAZARR trying to connect to Radarr SignalR feed...|
06/01/2024 23:31:51|INFO    |root                            |BAZARR is started and waiting for request on http://***.***.***.***:6767|
06/01/2024 23:40:33|INFO    |root                            |BAZARR trying to connect to Sonarr SignalR feed...|
06/01/2024 23:40:33|INFO    |root                            |BAZARR trying to connect to Radarr SignalR feed...|
06/01/2024 23:40:33|INFO    |root                            |BAZARR is started and waiting for request on http://***.***.***.***:6767|
06/01/2024 23:46:49|INFO    |root                            |BAZARR trying to connect to Sonarr SignalR feed...|
06/01/2024 23:46:49|INFO    |root                            |BAZARR trying to connect to Radarr SignalR feed...|
06/01/2024 23:46:49|INFO    |root                            |BAZARR is started and waiting for request on http://***.***.***.***:6767|
06/01/2024 23:52:20|INFO    |root                            |BAZARR trying to connect to Sonarr SignalR feed...|
06/01/2024 23:52:20|INFO    |root                            |BAZARR trying to connect to Radarr SignalR feed...|
06/01/2024 23:52:20|INFO    |root                            |BAZARR is started and waiting for request on http://***.***.***.***:6767|
