04/01/2024 18:44:09|INFO    |root                            |BAZARR trying to connect to Sonarr SignalR feed...|
04/01/2024 18:44:09|INFO    |root                            |BAZARR is started and waiting for request on http://***.***.***.***:6767|
04/01/2024 18:59:22|ERROR   |root                            |BAZARR Error trying to get rootfolder from Sonarr. Connection Error.|'Traceback (most recent call last):\n  File "/app/bazarr/bin/bazarr/../libs/urllib3/connection.py", line 174, in _new_conn\n    conn = connection.create_connection(\n           ^^^^^^^^^^^^^^^^^^^^^^^^^^^^^\n  File "/app/bazarr/bin/bazarr/../libs/subliminal_patch/http.py", line 325, in patched_create_connection\n    return _orig_create_connection(address, *args, **kwargs)\n           ^^^^^^^^^^^^^^^^^^^^^^^^^^^^^^^^^^^^^^^^^^^^^^^^^\n  File "/app/bazarr/bin/bazarr/../libs/urllib3/util/connection.py", line 95, in create_connection\n    raise err\n  File "/app/bazarr/bin/bazarr/../libs/urllib3/util/connection.py", line 85, in create_connection\n    sock.connect(sa)\nTimeoutError: timed out\n\nDuring handling of the above exception, another exception occurred:\n\nTraceback (most recent call last):\n  File "/app/bazarr/bin/bazarr/../libs/urllib3/connectionpool.py", line 703, in urlopen\n    httplib_response = self._make_request(\n                       ^^^^^^^^^^^^^^^^^^^\n  File "/app/bazarr/bin/bazarr/../libs/urllib3/connectionpool.py", line 398, in _make_request\n    conn.request(method, url, **httplib_request_kw)\n  File "/app/bazarr/bin/bazarr/../libs/urllib3/connection.py", line 239, in request\n    super(HTTPConnection, self).request(method, url, body=body, headers=headers)\n  File "/usr/lib/python3.11/http/client.py", line 1286, in request\n    self._send_request(method, url, body, headers, encode_chunked)\n  File "/usr/lib/python3.11/http/client.py", line 1332, in _send_request\n    self.endheaders(body, encode_chunked=encode_chunked)\n  File "/usr/lib/python3.11/http/client.py", line 1281, in endheaders\n    self._send_output(message_body, encode_chunked=encode_chunked)\n  File "/usr/lib/python3.11/http/client.py", line 1041, in _send_output\n    self.send(msg)\n  File "/usr/lib/python3.11/http/client.py", line 979, in send\n    self.connect()\n  File "/app/bazarr/bin/bazarr/../libs/urllib3/connection.py", line 205, in connect\n    conn = self._new_conn()\n           ^^^^^^^^^^^^^^^^\n  File "/app/bazarr/bin/bazarr/../libs/urllib3/connection.py", line 179, in _new_conn\n    raise ConnectTimeoutError(\nurllib3.exceptions.ConnectTimeoutError: (<urllib3.connection.HTTPConnection object at 0x7f1b0f0e2790>, \'Connection to ***.***.***.*** timed out. (connect timeout=60)\')\n\nDuring handling of the above exception, another exception occurred:\n\nTraceback (most recent call last):\n  File "/app/bazarr/bin/bazarr/../libs/requests/adapters.py", line 489, in send\n    resp = conn.urlopen(\n           ^^^^^^^^^^^^^\n  File "/app/bazarr/bin/bazarr/../libs/urllib3/connectionpool.py", line 787, in urlopen\n    retries = retries.increment(\n              ^^^^^^^^^^^^^^^^^^\n  File "/app/bazarr/bin/bazarr/../libs/urllib3/util/retry.py", line 592, in increment\n    raise MaxRetryError(_pool, url, error or ResponseError(cause))\nurllib3.exceptions.MaxRetryError: HTTPConnectionPool(host=\'***.***.***.***\', port=8989): Max retries exceeded with url: /api/v3/rootfolder?apikey=(removed) (Caused by ConnectTimeoutError(<urllib3.connection.HTTPConnection object at 0x7f1b0f0e2790>, \'Connection to ***.***.***.*** timed out. (connect timeout=60)\'))\n\nDuring handling of the above exception, another exception occurred:\n\nTraceback (most recent call last):\n  File "/app/bazarr/bin/bazarr/sonarr/rootfolder.py", line 22, in get_sonarr_rootfolder\n    rootfolder = requests.get(url_sonarr_api_rootfolder, timeout=int(settings.sonarr.http_timeout), verify=False, headers=headers)\n                 ^^^^^^^^^^^^^^^^^^^^^^^^^^^^^^^^^^^^^^^^^^^^^^^^^^^^^^^^^^^^^^^^^^^^^^^^^^^^^^^^^^^^^^^^^^^^^^^^^^^^^^^^^^^^^^^^^\n  File "/app/bazarr/bin/bazarr/../libs/requests/api.py", line 73, in get\n    return request("get", url, params=params, **kwargs)\n           ^^^^^^^^^^^^^^^^^^^^^^^^^^^^^^^^^^^^^^^^^^^^\n  File "/app/bazarr/bin/bazarr/../libs/requests/api.py", line 59, in request\n    return session.request(method=method, url=url, **kwargs)\n           ^^^^^^^^^^^^^^^^^^^^^^^^^^^^^^^^^^^^^^^^^^^^^^^^^\n  File "/app/bazarr/bin/bazarr/../libs/requests/sessions.py", line 587, in request\n    resp = self.send(prep, **send_kwargs)\n           ^^^^^^^^^^^^^^^^^^^^^^^^^^^^^^\n  File "/app/bazarr/bin/bazarr/../libs/requests/sessions.py", line 701, in send\n    r = adapter.send(request, **kwargs)\n        ^^^^^^^^^^^^^^^^^^^^^^^^^^^^^^^\n  File "/app/bazarr/bin/bazarr/../libs/requests/adapters.py", line 553, in send\n    raise ConnectTimeout(e, request=request)\nrequests.exceptions.ConnectTimeout: HTTPConnectionPool(host=\'***.***.***.***\', port=8989): Max retries exceeded with url: /api/v3/rootfolder?apikey=(removed) (Caused by ConnectTimeoutError(<urllib3.connection.HTTPConnection object at 0x7f1b0f0e2790>, \'Connection to ***.***.***.*** timed out. (connect timeout=60)\'))'|
04/01/2024 19:01:22|ERROR   |root                            |BAZARR Error trying to get tags from Sonarr. Connection Error.|'Traceback (most recent call last):\n  File "/app/bazarr/bin/bazarr/../libs/urllib3/connection.py", line 174, in _new_conn\n    conn = connection.create_connection(\n           ^^^^^^^^^^^^^^^^^^^^^^^^^^^^^\n  File "/app/bazarr/bin/bazarr/../libs/subliminal_patch/http.py", line 325, in patched_create_connection\n    return _orig_create_connection(address, *args, **kwargs)\n           ^^^^^^^^^^^^^^^^^^^^^^^^^^^^^^^^^^^^^^^^^^^^^^^^^\n  File "/app/bazarr/bin/bazarr/../libs/urllib3/util/connection.py", line 95, in create_connection\n    raise err\n  File "/app/bazarr/bin/bazarr/../libs/urllib3/util/connection.py", line 85, in create_connection\n    sock.connect(sa)\nTimeoutError: timed out\n\nDuring handling of the above exception, another exception occurred:\n\nTraceback (most recent call last):\n  File "/app/bazarr/bin/bazarr/../libs/urllib3/connectionpool.py", line 703, in urlopen\n    httplib_response = self._make_request(\n                       ^^^^^^^^^^^^^^^^^^^\n  File "/app/bazarr/bin/bazarr/../libs/urllib3/connectionpool.py", line 398, in _make_request\n    conn.request(method, url, **httplib_request_kw)\n  File "/app/bazarr/bin/bazarr/../libs/urllib3/connection.py", line 239, in request\n    super(HTTPConnection, self).request(method, url, body=body, headers=headers)\n  File "/usr/lib/python3.11/http/client.py", line 1286, in request\n    self._send_request(method, url, body, headers, encode_chunked)\n  File "/usr/lib/python3.11/http/client.py", line 1332, in _send_request\n    self.endheaders(body, encode_chunked=encode_chunked)\n  File "/usr/lib/python3.11/http/client.py", line 1281, in endheaders\n    self._send_output(message_body, encode_chunked=encode_chunked)\n  File "/usr/lib/python3.11/http/client.py", line 1041, in _send_output\n    self.send(msg)\n  File "/usr/lib/python3.11/http/client.py", line 979, in send\n    self.connect()\n  File "/app/bazarr/bin/bazarr/../libs/urllib3/connection.py", line 205, in connect\n    conn = self._new_conn()\n           ^^^^^^^^^^^^^^^^\n  File "/app/bazarr/bin/bazarr/../libs/urllib3/connection.py", line 179, in _new_conn\n    raise ConnectTimeoutError(\nurllib3.exceptions.ConnectTimeoutError: (<urllib3.connection.HTTPConnection object at 0x7f1b01241110>, \'Connection to ***.***.***.*** timed out. (connect timeout=60)\')\n\nDuring handling of the above exception, another exception occurred:\n\nTraceback (most recent call last):\n  File "/app/bazarr/bin/bazarr/../libs/requests/adapters.py", line 489, in send\n    resp = conn.urlopen(\n           ^^^^^^^^^^^^^\n  File "/app/bazarr/bin/bazarr/../libs/urllib3/connectionpool.py", line 787, in urlopen\n    retries = retries.increment(\n              ^^^^^^^^^^^^^^^^^^\n  File "/app/bazarr/bin/bazarr/../libs/urllib3/util/retry.py", line 592, in increment\n    raise MaxRetryError(_pool, url, error or ResponseError(cause))\nurllib3.exceptions.MaxRetryError: HTTPConnectionPool(host=\'***.***.***.***\', port=8989): Max retries exceeded with url: /api/v3/tag?apikey=(removed) (Caused by ConnectTimeoutError(<urllib3.connection.HTTPConnection object at 0x7f1b01241110>, \'Connection to ***.***.***.*** timed out. (connect timeout=60)\'))\n\nDuring handling of the above exception, another exception occurred:\n\nTraceback (most recent call last):\n  File "/app/bazarr/bin/bazarr/sonarr/sync/utils.py", line 56, in get_tags\n    tagsDict = requests.get(url_sonarr_api_series, timeout=int(settings.sonarr.http_timeout), verify=False, headers=headers)\n               ^^^^^^^^^^^^^^^^^^^^^^^^^^^^^^^^^^^^^^^^^^^^^^^^^^^^^^^^^^^^^^^^^^^^^^^^^^^^^^^^^^^^^^^^^^^^^^^^^^^^^^^^^^^^^\n  File "/app/bazarr/bin/bazarr/../libs/requests/api.py", line 73, in get\n    return request("get", url, params=params, **kwargs)\n           ^^^^^^^^^^^^^^^^^^^^^^^^^^^^^^^^^^^^^^^^^^^^\n  File "/app/bazarr/bin/bazarr/../libs/requests/api.py", line 59, in request\n    return session.request(method=method, url=url, **kwargs)\n           ^^^^^^^^^^^^^^^^^^^^^^^^^^^^^^^^^^^^^^^^^^^^^^^^^\n  File "/app/bazarr/bin/bazarr/../libs/requests/sessions.py", line 587, in request\n    resp = self.send(prep, **send_kwargs)\n           ^^^^^^^^^^^^^^^^^^^^^^^^^^^^^^\n  File "/app/bazarr/bin/bazarr/../libs/requests/sessions.py", line 701, in send\n    r = adapter.send(request, **kwargs)\n        ^^^^^^^^^^^^^^^^^^^^^^^^^^^^^^^\n  File "/app/bazarr/bin/bazarr/../libs/requests/adapters.py", line 553, in send\n    raise ConnectTimeout(e, request=request)\nrequests.exceptions.ConnectTimeout: HTTPConnectionPool(host=\'***.***.***.***\', port=8989): Max retries exceeded with url: /api/v3/tag?apikey=(removed) (Caused by ConnectTimeoutError(<urllib3.connection.HTTPConnection object at 0x7f1b01241110>, \'Connection to ***.***.***.*** timed out. (connect timeout=60)\'))'|
04/01/2024 19:03:22|ERROR   |root                            |BAZARR Error trying to get series from Sonarr. Connection Error.|'Traceback (most recent call last):\n  File "/app/bazarr/bin/bazarr/../libs/urllib3/connection.py", line 174, in _new_conn\n    conn = connection.create_connection(\n           ^^^^^^^^^^^^^^^^^^^^^^^^^^^^^\n  File "/app/bazarr/bin/bazarr/../libs/subliminal_patch/http.py", line 325, in patched_create_connection\n    return _orig_create_connection(address, *args, **kwargs)\n           ^^^^^^^^^^^^^^^^^^^^^^^^^^^^^^^^^^^^^^^^^^^^^^^^^\n  File "/app/bazarr/bin/bazarr/../libs/urllib3/util/connection.py", line 95, in create_connection\n    raise err\n  File "/app/bazarr/bin/bazarr/../libs/urllib3/util/connection.py", line 85, in create_connection\n    sock.connect(sa)\nTimeoutError: timed out\n\nDuring handling of the above exception, another exception occurred:\n\nTraceback (most recent call last):\n  File "/app/bazarr/bin/bazarr/../libs/urllib3/connectionpool.py", line 703, in urlopen\n    httplib_response = self._make_request(\n                       ^^^^^^^^^^^^^^^^^^^\n  File "/app/bazarr/bin/bazarr/../libs/urllib3/connectionpool.py", line 398, in _make_request\n    conn.request(method, url, **httplib_request_kw)\n  File "/app/bazarr/bin/bazarr/../libs/urllib3/connection.py", line 239, in request\n    super(HTTPConnection, self).request(method, url, body=body, headers=headers)\n  File "/usr/lib/python3.11/http/client.py", line 1286, in request\n    self._send_request(method, url, body, headers, encode_chunked)\n  File "/usr/lib/python3.11/http/client.py", line 1332, in _send_request\n    self.endheaders(body, encode_chunked=encode_chunked)\n  File "/usr/lib/python3.11/http/client.py", line 1281, in endheaders\n    self._send_output(message_body, encode_chunked=encode_chunked)\n  File "/usr/lib/python3.11/http/client.py", line 1041, in _send_output\n    self.send(msg)\n  File "/usr/lib/python3.11/http/client.py", line 979, in send\n    self.connect()\n  File "/app/bazarr/bin/bazarr/../libs/urllib3/connection.py", line 205, in connect\n    conn = self._new_conn()\n           ^^^^^^^^^^^^^^^^\n  File "/app/bazarr/bin/bazarr/../libs/urllib3/connection.py", line 179, in _new_conn\n    raise ConnectTimeoutError(\nurllib3.exceptions.ConnectTimeoutError: (<urllib3.connection.HTTPConnection object at 0x7f1b010842d0>, \'Connection to ***.***.***.*** timed out. (connect timeout=60)\')\n\nDuring handling of the above exception, another exception occurred:\n\nTraceback (most recent call last):\n  File "/app/bazarr/bin/bazarr/../libs/requests/adapters.py", line 489, in send\n    resp = conn.urlopen(\n           ^^^^^^^^^^^^^\n  File "/app/bazarr/bin/bazarr/../libs/urllib3/connectionpool.py", line 787, in urlopen\n    retries = retries.increment(\n              ^^^^^^^^^^^^^^^^^^\n  File "/app/bazarr/bin/bazarr/../libs/urllib3/util/retry.py", line 592, in increment\n    raise MaxRetryError(_pool, url, error or ResponseError(cause))\nurllib3.exceptions.MaxRetryError: HTTPConnectionPool(host=\'***.***.***.***\', port=8989): Max retries exceeded with url: /api/v3/series/?apikey=(removed) (Caused by ConnectTimeoutError(<urllib3.connection.HTTPConnection object at 0x7f1b010842d0>, \'Connection to ***.***.***.*** timed out. (connect timeout=60)\'))\n\nDuring handling of the above exception, another exception occurred:\n\nTraceback (most recent call last):\n  File "/app/bazarr/bin/bazarr/sonarr/sync/utils.py", line 74, in get_series_from_sonarr_api\n    r = requests.get(url_sonarr_api_series, timeout=int(settings.sonarr.http_timeout), verify=False, headers=headers)\n        ^^^^^^^^^^^^^^^^^^^^^^^^^^^^^^^^^^^^^^^^^^^^^^^^^^^^^^^^^^^^^^^^^^^^^^^^^^^^^^^^^^^^^^^^^^^^^^^^^^^^^^^^^^^^^\n  File "/app/bazarr/bin/bazarr/../libs/requests/api.py", line 73, in get\n    return request("get", url, params=params, **kwargs)\n           ^^^^^^^^^^^^^^^^^^^^^^^^^^^^^^^^^^^^^^^^^^^^\n  File "/app/bazarr/bin/bazarr/../libs/requests/api.py", line 59, in request\n    return session.request(method=method, url=url, **kwargs)\n           ^^^^^^^^^^^^^^^^^^^^^^^^^^^^^^^^^^^^^^^^^^^^^^^^^\n  File "/app/bazarr/bin/bazarr/../libs/requests/sessions.py", line 587, in request\n    resp = self.send(prep, **send_kwargs)\n           ^^^^^^^^^^^^^^^^^^^^^^^^^^^^^^\n  File "/app/bazarr/bin/bazarr/../libs/requests/sessions.py", line 701, in send\n    r = adapter.send(request, **kwargs)\n        ^^^^^^^^^^^^^^^^^^^^^^^^^^^^^^^\n  File "/app/bazarr/bin/bazarr/../libs/requests/adapters.py", line 553, in send\n    raise ConnectTimeout(e, request=request)\nrequests.exceptions.ConnectTimeout: HTTPConnectionPool(host=\'***.***.***.***\', port=8989): Max retries exceeded with url: /api/v3/series/?apikey=(removed) (Caused by ConnectTimeoutError(<urllib3.connection.HTTPConnection object at 0x7f1b010842d0>, \'Connection to ***.***.***.*** timed out. (connect timeout=60)\'))'|
04/01/2024 19:14:22|ERROR   |root                            |BAZARR Error trying to get rootfolder from Sonarr. Connection Error.|'Traceback (most recent call last):\n  File "/app/bazarr/bin/bazarr/../libs/urllib3/connection.py", line 174, in _new_conn\n    conn = connection.create_connection(\n           ^^^^^^^^^^^^^^^^^^^^^^^^^^^^^\n  File "/app/bazarr/bin/bazarr/../libs/subliminal_patch/http.py", line 325, in patched_create_connection\n    return _orig_create_connection(address, *args, **kwargs)\n           ^^^^^^^^^^^^^^^^^^^^^^^^^^^^^^^^^^^^^^^^^^^^^^^^^\n  File "/app/bazarr/bin/bazarr/../libs/urllib3/util/connection.py", line 95, in create_connection\n    raise err\n  File "/app/bazarr/bin/bazarr/../libs/urllib3/util/connection.py", line 85, in create_connection\n    sock.connect(sa)\nTimeoutError: timed out\n\nDuring handling of the above exception, another exception occurred:\n\nTraceback (most recent call last):\n  File "/app/bazarr/bin/bazarr/../libs/urllib3/connectionpool.py", line 703, in urlopen\n    httplib_response = self._make_request(\n                       ^^^^^^^^^^^^^^^^^^^\n  File "/app/bazarr/bin/bazarr/../libs/urllib3/connectionpool.py", line 398, in _make_request\n    conn.request(method, url, **httplib_request_kw)\n  File "/app/bazarr/bin/bazarr/../libs/urllib3/connection.py", line 239, in request\n    super(HTTPConnection, self).request(method, url, body=body, headers=headers)\n  File "/usr/lib/python3.11/http/client.py", line 1286, in request\n    self._send_request(method, url, body, headers, encode_chunked)\n  File "/usr/lib/python3.11/http/client.py", line 1332, in _send_request\n    self.endheaders(body, encode_chunked=encode_chunked)\n  File "/usr/lib/python3.11/http/client.py", line 1281, in endheaders\n    self._send_output(message_body, encode_chunked=encode_chunked)\n  File "/usr/lib/python3.11/http/client.py", line 1041, in _send_output\n    self.send(msg)\n  File "/usr/lib/python3.11/http/client.py", line 979, in send\n    self.connect()\n  File "/app/bazarr/bin/bazarr/../libs/urllib3/connection.py", line 205, in connect\n    conn = self._new_conn()\n           ^^^^^^^^^^^^^^^^\n  File "/app/bazarr/bin/bazarr/../libs/urllib3/connection.py", line 179, in _new_conn\n    raise ConnectTimeoutError(\nurllib3.exceptions.ConnectTimeoutError: (<urllib3.connection.HTTPConnection object at 0x7f1b0f10f850>, \'Connection to ***.***.***.*** timed out. (connect timeout=60)\')\n\nDuring handling of the above exception, another exception occurred:\n\nTraceback (most recent call last):\n  File "/app/bazarr/bin/bazarr/../libs/requests/adapters.py", line 489, in send\n    resp = conn.urlopen(\n           ^^^^^^^^^^^^^\n  File "/app/bazarr/bin/bazarr/../libs/urllib3/connectionpool.py", line 787, in urlopen\n    retries = retries.increment(\n              ^^^^^^^^^^^^^^^^^^\n  File "/app/bazarr/bin/bazarr/../libs/urllib3/util/retry.py", line 592, in increment\n    raise MaxRetryError(_pool, url, error or ResponseError(cause))\nurllib3.exceptions.MaxRetryError: HTTPConnectionPool(host=\'***.***.***.***\', port=8989): Max retries exceeded with url: /api/v3/rootfolder?apikey=(removed) (Caused by ConnectTimeoutError(<urllib3.connection.HTTPConnection object at 0x7f1b0f10f850>, \'Connection to ***.***.***.*** timed out. (connect timeout=60)\'))\n\nDuring handling of the above exception, another exception occurred:\n\nTraceback (most recent call last):\n  File "/app/bazarr/bin/bazarr/sonarr/rootfolder.py", line 22, in get_sonarr_rootfolder\n    rootfolder = requests.get(url_sonarr_api_rootfolder, timeout=int(settings.sonarr.http_timeout), verify=False, headers=headers)\n                 ^^^^^^^^^^^^^^^^^^^^^^^^^^^^^^^^^^^^^^^^^^^^^^^^^^^^^^^^^^^^^^^^^^^^^^^^^^^^^^^^^^^^^^^^^^^^^^^^^^^^^^^^^^^^^^^^^\n  File "/app/bazarr/bin/bazarr/../libs/requests/api.py", line 73, in get\n    return request("get", url, params=params, **kwargs)\n           ^^^^^^^^^^^^^^^^^^^^^^^^^^^^^^^^^^^^^^^^^^^^\n  File "/app/bazarr/bin/bazarr/../libs/requests/api.py", line 59, in request\n    return session.request(method=method, url=url, **kwargs)\n           ^^^^^^^^^^^^^^^^^^^^^^^^^^^^^^^^^^^^^^^^^^^^^^^^^\n  File "/app/bazarr/bin/bazarr/../libs/requests/sessions.py", line 587, in request\n    resp = self.send(prep, **send_kwargs)\n           ^^^^^^^^^^^^^^^^^^^^^^^^^^^^^^\n  File "/app/bazarr/bin/bazarr/../libs/requests/sessions.py", line 701, in send\n    r = adapter.send(request, **kwargs)\n        ^^^^^^^^^^^^^^^^^^^^^^^^^^^^^^^\n  File "/app/bazarr/bin/bazarr/../libs/requests/adapters.py", line 553, in send\n    raise ConnectTimeout(e, request=request)\nrequests.exceptions.ConnectTimeout: HTTPConnectionPool(host=\'***.***.***.***\', port=8989): Max retries exceeded with url: /api/v3/rootfolder?apikey=(removed) (Caused by ConnectTimeoutError(<urllib3.connection.HTTPConnection object at 0x7f1b0f10f850>, \'Connection to ***.***.***.*** timed out. (connect timeout=60)\'))'|
04/01/2024 19:16:22|ERROR   |root                            |BAZARR Error trying to get tags from Sonarr. Connection Error.|'Traceback (most recent call last):\n  File "/app/bazarr/bin/bazarr/../libs/urllib3/connection.py", line 174, in _new_conn\n    conn = connection.create_connection(\n           ^^^^^^^^^^^^^^^^^^^^^^^^^^^^^\n  File "/app/bazarr/bin/bazarr/../libs/subliminal_patch/http.py", line 325, in patched_create_connection\n    return _orig_create_connection(address, *args, **kwargs)\n           ^^^^^^^^^^^^^^^^^^^^^^^^^^^^^^^^^^^^^^^^^^^^^^^^^\n  File "/app/bazarr/bin/bazarr/../libs/urllib3/util/connection.py", line 95, in create_connection\n    raise err\n  File "/app/bazarr/bin/bazarr/../libs/urllib3/util/connection.py", line 85, in create_connection\n    sock.connect(sa)\nTimeoutError: timed out\n\nDuring handling of the above exception, another exception occurred:\n\nTraceback (most recent call last):\n  File "/app/bazarr/bin/bazarr/../libs/urllib3/connectionpool.py", line 703, in urlopen\n    httplib_response = self._make_request(\n                       ^^^^^^^^^^^^^^^^^^^\n  File "/app/bazarr/bin/bazarr/../libs/urllib3/connectionpool.py", line 398, in _make_request\n    conn.request(method, url, **httplib_request_kw)\n  File "/app/bazarr/bin/bazarr/../libs/urllib3/connection.py", line 239, in request\n    super(HTTPConnection, self).request(method, url, body=body, headers=headers)\n  File "/usr/lib/python3.11/http/client.py", line 1286, in request\n    self._send_request(method, url, body, headers, encode_chunked)\n  File "/usr/lib/python3.11/http/client.py", line 1332, in _send_request\n    self.endheaders(body, encode_chunked=encode_chunked)\n  File "/usr/lib/python3.11/http/client.py", line 1281, in endheaders\n    self._send_output(message_body, encode_chunked=encode_chunked)\n  File "/usr/lib/python3.11/http/client.py", line 1041, in _send_output\n    self.send(msg)\n  File "/usr/lib/python3.11/http/client.py", line 979, in send\n    self.connect()\n  File "/app/bazarr/bin/bazarr/../libs/urllib3/connection.py", line 205, in connect\n    conn = self._new_conn()\n           ^^^^^^^^^^^^^^^^\n  File "/app/bazarr/bin/bazarr/../libs/urllib3/connection.py", line 179, in _new_conn\n    raise ConnectTimeoutError(\nurllib3.exceptions.ConnectTimeoutError: (<urllib3.connection.HTTPConnection object at 0x7f1b010b5d10>, \'Connection to ***.***.***.*** timed out. (connect timeout=60)\')\n\nDuring handling of the above exception, another exception occurred:\n\nTraceback (most recent call last):\n  File "/app/bazarr/bin/bazarr/../libs/requests/adapters.py", line 489, in send\n    resp = conn.urlopen(\n           ^^^^^^^^^^^^^\n  File "/app/bazarr/bin/bazarr/../libs/urllib3/connectionpool.py", line 787, in urlopen\n    retries = retries.increment(\n              ^^^^^^^^^^^^^^^^^^\n  File "/app/bazarr/bin/bazarr/../libs/urllib3/util/retry.py", line 592, in increment\n    raise MaxRetryError(_pool, url, error or ResponseError(cause))\nurllib3.exceptions.MaxRetryError: HTTPConnectionPool(host=\'***.***.***.***\', port=8989): Max retries exceeded with url: /api/v3/tag?apikey=(removed) (Caused by ConnectTimeoutError(<urllib3.connection.HTTPConnection object at 0x7f1b010b5d10>, \'Connection to ***.***.***.*** timed out. (connect timeout=60)\'))\n\nDuring handling of the above exception, another exception occurred:\n\nTraceback (most recent call last):\n  File "/app/bazarr/bin/bazarr/sonarr/sync/utils.py", line 56, in get_tags\n    tagsDict = requests.get(url_sonarr_api_series, timeout=int(settings.sonarr.http_timeout), verify=False, headers=headers)\n               ^^^^^^^^^^^^^^^^^^^^^^^^^^^^^^^^^^^^^^^^^^^^^^^^^^^^^^^^^^^^^^^^^^^^^^^^^^^^^^^^^^^^^^^^^^^^^^^^^^^^^^^^^^^^^\n  File "/app/bazarr/bin/bazarr/../libs/requests/api.py", line 73, in get\n    return request("get", url, params=params, **kwargs)\n           ^^^^^^^^^^^^^^^^^^^^^^^^^^^^^^^^^^^^^^^^^^^^\n  File "/app/bazarr/bin/bazarr/../libs/requests/api.py", line 59, in request\n    return session.request(method=method, url=url, **kwargs)\n           ^^^^^^^^^^^^^^^^^^^^^^^^^^^^^^^^^^^^^^^^^^^^^^^^^\n  File "/app/bazarr/bin/bazarr/../libs/requests/sessions.py", line 587, in request\n    resp = self.send(prep, **send_kwargs)\n           ^^^^^^^^^^^^^^^^^^^^^^^^^^^^^^\n  File "/app/bazarr/bin/bazarr/../libs/requests/sessions.py", line 701, in send\n    r = adapter.send(request, **kwargs)\n        ^^^^^^^^^^^^^^^^^^^^^^^^^^^^^^^\n  File "/app/bazarr/bin/bazarr/../libs/requests/adapters.py", line 553, in send\n    raise ConnectTimeout(e, request=request)\nrequests.exceptions.ConnectTimeout: HTTPConnectionPool(host=\'***.***.***.***\', port=8989): Max retries exceeded with url: /api/v3/tag?apikey=(removed) (Caused by ConnectTimeoutError(<urllib3.connection.HTTPConnection object at 0x7f1b010b5d10>, \'Connection to ***.***.***.*** timed out. (connect timeout=60)\'))'|
04/01/2024 19:18:22|ERROR   |root                            |BAZARR Error trying to get series from Sonarr. Connection Error.|'Traceback (most recent call last):\n  File "/app/bazarr/bin/bazarr/../libs/urllib3/connection.py", line 174, in _new_conn\n    conn = connection.create_connection(\n           ^^^^^^^^^^^^^^^^^^^^^^^^^^^^^\n  File "/app/bazarr/bin/bazarr/../libs/subliminal_patch/http.py", line 325, in patched_create_connection\n    return _orig_create_connection(address, *args, **kwargs)\n           ^^^^^^^^^^^^^^^^^^^^^^^^^^^^^^^^^^^^^^^^^^^^^^^^^\n  File "/app/bazarr/bin/bazarr/../libs/urllib3/util/connection.py", line 95, in create_connection\n    raise err\n  File "/app/bazarr/bin/bazarr/../libs/urllib3/util/connection.py", line 85, in create_connection\n    sock.connect(sa)\nTimeoutError: timed out\n\nDuring handling of the above exception, another exception occurred:\n\nTraceback (most recent call last):\n  File "/app/bazarr/bin/bazarr/../libs/urllib3/connectionpool.py", line 703, in urlopen\n    httplib_response = self._make_request(\n                       ^^^^^^^^^^^^^^^^^^^\n  File "/app/bazarr/bin/bazarr/../libs/urllib3/connectionpool.py", line 398, in _make_request\n    conn.request(method, url, **httplib_request_kw)\n  File "/app/bazarr/bin/bazarr/../libs/urllib3/connection.py", line 239, in request\n    super(HTTPConnection, self).request(method, url, body=body, headers=headers)\n  File "/usr/lib/python3.11/http/client.py", line 1286, in request\n    self._send_request(method, url, body, headers, encode_chunked)\n  File "/usr/lib/python3.11/http/client.py", line 1332, in _send_request\n    self.endheaders(body, encode_chunked=encode_chunked)\n  File "/usr/lib/python3.11/http/client.py", line 1281, in endheaders\n    self._send_output(message_body, encode_chunked=encode_chunked)\n  File "/usr/lib/python3.11/http/client.py", line 1041, in _send_output\n    self.send(msg)\n  File "/usr/lib/python3.11/http/client.py", line 979, in send\n    self.connect()\n  File "/app/bazarr/bin/bazarr/../libs/urllib3/connection.py", line 205, in connect\n    conn = self._new_conn()\n           ^^^^^^^^^^^^^^^^\n  File "/app/bazarr/bin/bazarr/../libs/urllib3/connection.py", line 179, in _new_conn\n    raise ConnectTimeoutError(\nurllib3.exceptions.ConnectTimeoutError: (<urllib3.connection.HTTPConnection object at 0x7f1b01152f50>, \'Connection to ***.***.***.*** timed out. (connect timeout=60)\')\n\nDuring handling of the above exception, another exception occurred:\n\nTraceback (most recent call last):\n  File "/app/bazarr/bin/bazarr/../libs/requests/adapters.py", line 489, in send\n    resp = conn.urlopen(\n           ^^^^^^^^^^^^^\n  File "/app/bazarr/bin/bazarr/../libs/urllib3/connectionpool.py", line 787, in urlopen\n    retries = retries.increment(\n              ^^^^^^^^^^^^^^^^^^\n  File "/app/bazarr/bin/bazarr/../libs/urllib3/util/retry.py", line 592, in increment\n    raise MaxRetryError(_pool, url, error or ResponseError(cause))\nurllib3.exceptions.MaxRetryError: HTTPConnectionPool(host=\'***.***.***.***\', port=8989): Max retries exceeded with url: /api/v3/series/?apikey=(removed) (Caused by ConnectTimeoutError(<urllib3.connection.HTTPConnection object at 0x7f1b01152f50>, \'Connection to ***.***.***.*** timed out. (connect timeout=60)\'))\n\nDuring handling of the above exception, another exception occurred:\n\nTraceback (most recent call last):\n  File "/app/bazarr/bin/bazarr/sonarr/sync/utils.py", line 74, in get_series_from_sonarr_api\n    r = requests.get(url_sonarr_api_series, timeout=int(settings.sonarr.http_timeout), verify=False, headers=headers)\n        ^^^^^^^^^^^^^^^^^^^^^^^^^^^^^^^^^^^^^^^^^^^^^^^^^^^^^^^^^^^^^^^^^^^^^^^^^^^^^^^^^^^^^^^^^^^^^^^^^^^^^^^^^^^^^\n  File "/app/bazarr/bin/bazarr/../libs/requests/api.py", line 73, in get\n    return request("get", url, params=params, **kwargs)\n           ^^^^^^^^^^^^^^^^^^^^^^^^^^^^^^^^^^^^^^^^^^^^\n  File "/app/bazarr/bin/bazarr/../libs/requests/api.py", line 59, in request\n    return session.request(method=method, url=url, **kwargs)\n           ^^^^^^^^^^^^^^^^^^^^^^^^^^^^^^^^^^^^^^^^^^^^^^^^^\n  File "/app/bazarr/bin/bazarr/../libs/requests/sessions.py", line 587, in request\n    resp = self.send(prep, **send_kwargs)\n           ^^^^^^^^^^^^^^^^^^^^^^^^^^^^^^\n  File "/app/bazarr/bin/bazarr/../libs/requests/sessions.py", line 701, in send\n    r = adapter.send(request, **kwargs)\n        ^^^^^^^^^^^^^^^^^^^^^^^^^^^^^^^\n  File "/app/bazarr/bin/bazarr/../libs/requests/adapters.py", line 553, in send\n    raise ConnectTimeout(e, request=request)\nrequests.exceptions.ConnectTimeout: HTTPConnectionPool(host=\'***.***.***.***\', port=8989): Max retries exceeded with url: /api/v3/series/?apikey=(removed) (Caused by ConnectTimeoutError(<urllib3.connection.HTTPConnection object at 0x7f1b01152f50>, \'Connection to ***.***.***.*** timed out. (connect timeout=60)\'))'|
04/01/2024 19:29:22|ERROR   |root                            |BAZARR Error trying to get rootfolder from Sonarr. Connection Error.|'Traceback (most recent call last):\n  File "/app/bazarr/bin/bazarr/../libs/urllib3/connection.py", line 174, in _new_conn\n    conn = connection.create_connection(\n           ^^^^^^^^^^^^^^^^^^^^^^^^^^^^^\n  File "/app/bazarr/bin/bazarr/../libs/subliminal_patch/http.py", line 325, in patched_create_connection\n    return _orig_create_connection(address, *args, **kwargs)\n           ^^^^^^^^^^^^^^^^^^^^^^^^^^^^^^^^^^^^^^^^^^^^^^^^^\n  File "/app/bazarr/bin/bazarr/../libs/urllib3/util/connection.py", line 95, in create_connection\n    raise err\n  File "/app/bazarr/bin/bazarr/../libs/urllib3/util/connection.py", line 85, in create_connection\n    sock.connect(sa)\nTimeoutError: timed out\n\nDuring handling of the above exception, another exception occurred:\n\nTraceback (most recent call last):\n  File "/app/bazarr/bin/bazarr/../libs/urllib3/connectionpool.py", line 703, in urlopen\n    httplib_response = self._make_request(\n                       ^^^^^^^^^^^^^^^^^^^\n  File "/app/bazarr/bin/bazarr/../libs/urllib3/connectionpool.py", line 398, in _make_request\n    conn.request(method, url, **httplib_request_kw)\n  File "/app/bazarr/bin/bazarr/../libs/urllib3/connection.py", line 239, in request\n    super(HTTPConnection, self).request(method, url, body=body, headers=headers)\n  File "/usr/lib/python3.11/http/client.py", line 1286, in request\n    self._send_request(method, url, body, headers, encode_chunked)\n  File "/usr/lib/python3.11/http/client.py", line 1332, in _send_request\n    self.endheaders(body, encode_chunked=encode_chunked)\n  File "/usr/lib/python3.11/http/client.py", line 1281, in endheaders\n    self._send_output(message_body, encode_chunked=encode_chunked)\n  File "/usr/lib/python3.11/http/client.py", line 1041, in _send_output\n    self.send(msg)\n  File "/usr/lib/python3.11/http/client.py", line 979, in send\n    self.connect()\n  File "/app/bazarr/bin/bazarr/../libs/urllib3/connection.py", line 205, in connect\n    conn = self._new_conn()\n           ^^^^^^^^^^^^^^^^\n  File "/app/bazarr/bin/bazarr/../libs/urllib3/connection.py", line 179, in _new_conn\n    raise ConnectTimeoutError(\nurllib3.exceptions.ConnectTimeoutError: (<urllib3.connection.HTTPConnection object at 0x7f1b0f0e3550>, \'Connection to ***.***.***.*** timed out. (connect timeout=60)\')\n\nDuring handling of the above exception, another exception occurred:\n\nTraceback (most recent call last):\n  File "/app/bazarr/bin/bazarr/../libs/requests/adapters.py", line 489, in send\n    resp = conn.urlopen(\n           ^^^^^^^^^^^^^\n  File "/app/bazarr/bin/bazarr/../libs/urllib3/connectionpool.py", line 787, in urlopen\n    retries = retries.increment(\n              ^^^^^^^^^^^^^^^^^^\n  File "/app/bazarr/bin/bazarr/../libs/urllib3/util/retry.py", line 592, in increment\n    raise MaxRetryError(_pool, url, error or ResponseError(cause))\nurllib3.exceptions.MaxRetryError: HTTPConnectionPool(host=\'***.***.***.***\', port=8989): Max retries exceeded with url: /api/v3/rootfolder?apikey=(removed) (Caused by ConnectTimeoutError(<urllib3.connection.HTTPConnection object at 0x7f1b0f0e3550>, \'Connection to ***.***.***.*** timed out. (connect timeout=60)\'))\n\nDuring handling of the above exception, another exception occurred:\n\nTraceback (most recent call last):\n  File "/app/bazarr/bin/bazarr/sonarr/rootfolder.py", line 22, in get_sonarr_rootfolder\n    rootfolder = requests.get(url_sonarr_api_rootfolder, timeout=int(settings.sonarr.http_timeout), verify=False, headers=headers)\n                 ^^^^^^^^^^^^^^^^^^^^^^^^^^^^^^^^^^^^^^^^^^^^^^^^^^^^^^^^^^^^^^^^^^^^^^^^^^^^^^^^^^^^^^^^^^^^^^^^^^^^^^^^^^^^^^^^^\n  File "/app/bazarr/bin/bazarr/../libs/requests/api.py", line 73, in get\n    return request("get", url, params=params, **kwargs)\n           ^^^^^^^^^^^^^^^^^^^^^^^^^^^^^^^^^^^^^^^^^^^^\n  File "/app/bazarr/bin/bazarr/../libs/requests/api.py", line 59, in request\n    return session.request(method=method, url=url, **kwargs)\n           ^^^^^^^^^^^^^^^^^^^^^^^^^^^^^^^^^^^^^^^^^^^^^^^^^\n  File "/app/bazarr/bin/bazarr/../libs/requests/sessions.py", line 587, in request\n    resp = self.send(prep, **send_kwargs)\n           ^^^^^^^^^^^^^^^^^^^^^^^^^^^^^^\n  File "/app/bazarr/bin/bazarr/../libs/requests/sessions.py", line 701, in send\n    r = adapter.send(request, **kwargs)\n        ^^^^^^^^^^^^^^^^^^^^^^^^^^^^^^^\n  File "/app/bazarr/bin/bazarr/../libs/requests/adapters.py", line 553, in send\n    raise ConnectTimeout(e, request=request)\nrequests.exceptions.ConnectTimeout: HTTPConnectionPool(host=\'***.***.***.***\', port=8989): Max retries exceeded with url: /api/v3/rootfolder?apikey=(removed) (Caused by ConnectTimeoutError(<urllib3.connection.HTTPConnection object at 0x7f1b0f0e3550>, \'Connection to ***.***.***.*** timed out. (connect timeout=60)\'))'|
04/01/2024 19:31:22|ERROR   |root                            |BAZARR Error trying to get tags from Sonarr. Connection Error.|'Traceback (most recent call last):\n  File "/app/bazarr/bin/bazarr/../libs/urllib3/connection.py", line 174, in _new_conn\n    conn = connection.create_connection(\n           ^^^^^^^^^^^^^^^^^^^^^^^^^^^^^\n  File "/app/bazarr/bin/bazarr/../libs/subliminal_patch/http.py", line 325, in patched_create_connection\n    return _orig_create_connection(address, *args, **kwargs)\n           ^^^^^^^^^^^^^^^^^^^^^^^^^^^^^^^^^^^^^^^^^^^^^^^^^\n  File "/app/bazarr/bin/bazarr/../libs/urllib3/util/connection.py", line 95, in create_connection\n    raise err\n  File "/app/bazarr/bin/bazarr/../libs/urllib3/util/connection.py", line 85, in create_connection\n    sock.connect(sa)\nTimeoutError: timed out\n\nDuring handling of the above exception, another exception occurred:\n\nTraceback (most recent call last):\n  File "/app/bazarr/bin/bazarr/../libs/urllib3/connectionpool.py", line 703, in urlopen\n    httplib_response = self._make_request(\n                       ^^^^^^^^^^^^^^^^^^^\n  File "/app/bazarr/bin/bazarr/../libs/urllib3/connectionpool.py", line 398, in _make_request\n    conn.request(method, url, **httplib_request_kw)\n  File "/app/bazarr/bin/bazarr/../libs/urllib3/connection.py", line 239, in request\n    super(HTTPConnection, self).request(method, url, body=body, headers=headers)\n  File "/usr/lib/python3.11/http/client.py", line 1286, in request\n    self._send_request(method, url, body, headers, encode_chunked)\n  File "/usr/lib/python3.11/http/client.py", line 1332, in _send_request\n    self.endheaders(body, encode_chunked=encode_chunked)\n  File "/usr/lib/python3.11/http/client.py", line 1281, in endheaders\n    self._send_output(message_body, encode_chunked=encode_chunked)\n  File "/usr/lib/python3.11/http/client.py", line 1041, in _send_output\n    self.send(msg)\n  File "/usr/lib/python3.11/http/client.py", line 979, in send\n    self.connect()\n  File "/app/bazarr/bin/bazarr/../libs/urllib3/connection.py", line 205, in connect\n    conn = self._new_conn()\n           ^^^^^^^^^^^^^^^^\n  File "/app/bazarr/bin/bazarr/../libs/urllib3/connection.py", line 179, in _new_conn\n    raise ConnectTimeoutError(\nurllib3.exceptions.ConnectTimeoutError: (<urllib3.connection.HTTPConnection object at 0x7f1b0f0e3850>, \'Connection to ***.***.***.*** timed out. (connect timeout=60)\')\n\nDuring handling of the above exception, another exception occurred:\n\nTraceback (most recent call last):\n  File "/app/bazarr/bin/bazarr/../libs/requests/adapters.py", line 489, in send\n    resp = conn.urlopen(\n           ^^^^^^^^^^^^^\n  File "/app/bazarr/bin/bazarr/../libs/urllib3/connectionpool.py", line 787, in urlopen\n    retries = retries.increment(\n              ^^^^^^^^^^^^^^^^^^\n  File "/app/bazarr/bin/bazarr/../libs/urllib3/util/retry.py", line 592, in increment\n    raise MaxRetryError(_pool, url, error or ResponseError(cause))\nurllib3.exceptions.MaxRetryError: HTTPConnectionPool(host=\'***.***.***.***\', port=8989): Max retries exceeded with url: /api/v3/tag?apikey=(removed) (Caused by ConnectTimeoutError(<urllib3.connection.HTTPConnection object at 0x7f1b0f0e3850>, \'Connection to ***.***.***.*** timed out. (connect timeout=60)\'))\n\nDuring handling of the above exception, another exception occurred:\n\nTraceback (most recent call last):\n  File "/app/bazarr/bin/bazarr/sonarr/sync/utils.py", line 56, in get_tags\n    tagsDict = requests.get(url_sonarr_api_series, timeout=int(settings.sonarr.http_timeout), verify=False, headers=headers)\n               ^^^^^^^^^^^^^^^^^^^^^^^^^^^^^^^^^^^^^^^^^^^^^^^^^^^^^^^^^^^^^^^^^^^^^^^^^^^^^^^^^^^^^^^^^^^^^^^^^^^^^^^^^^^^^\n  File "/app/bazarr/bin/bazarr/../libs/requests/api.py", line 73, in get\n    return request("get", url, params=params, **kwargs)\n           ^^^^^^^^^^^^^^^^^^^^^^^^^^^^^^^^^^^^^^^^^^^^\n  File "/app/bazarr/bin/bazarr/../libs/requests/api.py", line 59, in request\n    return session.request(method=method, url=url, **kwargs)\n           ^^^^^^^^^^^^^^^^^^^^^^^^^^^^^^^^^^^^^^^^^^^^^^^^^\n  File "/app/bazarr/bin/bazarr/../libs/requests/sessions.py", line 587, in request\n    resp = self.send(prep, **send_kwargs)\n           ^^^^^^^^^^^^^^^^^^^^^^^^^^^^^^\n  File "/app/bazarr/bin/bazarr/../libs/requests/sessions.py", line 701, in send\n    r = adapter.send(request, **kwargs)\n        ^^^^^^^^^^^^^^^^^^^^^^^^^^^^^^^\n  File "/app/bazarr/bin/bazarr/../libs/requests/adapters.py", line 553, in send\n    raise ConnectTimeout(e, request=request)\nrequests.exceptions.ConnectTimeout: HTTPConnectionPool(host=\'***.***.***.***\', port=8989): Max retries exceeded with url: /api/v3/tag?apikey=(removed) (Caused by ConnectTimeoutError(<urllib3.connection.HTTPConnection object at 0x7f1b0f0e3850>, \'Connection to ***.***.***.*** timed out. (connect timeout=60)\'))'|
04/01/2024 19:33:22|ERROR   |root                            |BAZARR Error trying to get series from Sonarr. Connection Error.|'Traceback (most recent call last):\n  File "/app/bazarr/bin/bazarr/../libs/urllib3/connection.py", line 174, in _new_conn\n    conn = connection.create_connection(\n           ^^^^^^^^^^^^^^^^^^^^^^^^^^^^^\n  File "/app/bazarr/bin/bazarr/../libs/subliminal_patch/http.py", line 325, in patched_create_connection\n    return _orig_create_connection(address, *args, **kwargs)\n           ^^^^^^^^^^^^^^^^^^^^^^^^^^^^^^^^^^^^^^^^^^^^^^^^^\n  File "/app/bazarr/bin/bazarr/../libs/urllib3/util/connection.py", line 95, in create_connection\n    raise err\n  File "/app/bazarr/bin/bazarr/../libs/urllib3/util/connection.py", line 85, in create_connection\n    sock.connect(sa)\nTimeoutError: timed out\n\nDuring handling of the above exception, another exception occurred:\n\nTraceback (most recent call last):\n  File "/app/bazarr/bin/bazarr/../libs/urllib3/connectionpool.py", line 703, in urlopen\n    httplib_response = self._make_request(\n                       ^^^^^^^^^^^^^^^^^^^\n  File "/app/bazarr/bin/bazarr/../libs/urllib3/connectionpool.py", line 398, in _make_request\n    conn.request(method, url, **httplib_request_kw)\n  File "/app/bazarr/bin/bazarr/../libs/urllib3/connection.py", line 239, in request\n    super(HTTPConnection, self).request(method, url, body=body, headers=headers)\n  File "/usr/lib/python3.11/http/client.py", line 1286, in request\n    self._send_request(method, url, body, headers, encode_chunked)\n  File "/usr/lib/python3.11/http/client.py", line 1332, in _send_request\n    self.endheaders(body, encode_chunked=encode_chunked)\n  File "/usr/lib/python3.11/http/client.py", line 1281, in endheaders\n    self._send_output(message_body, encode_chunked=encode_chunked)\n  File "/usr/lib/python3.11/http/client.py", line 1041, in _send_output\n    self.send(msg)\n  File "/usr/lib/python3.11/http/client.py", line 979, in send\n    self.connect()\n  File "/app/bazarr/bin/bazarr/../libs/urllib3/connection.py", line 205, in connect\n    conn = self._new_conn()\n           ^^^^^^^^^^^^^^^^\n  File "/app/bazarr/bin/bazarr/../libs/urllib3/connection.py", line 179, in _new_conn\n    raise ConnectTimeoutError(\nurllib3.exceptions.ConnectTimeoutError: (<urllib3.connection.HTTPConnection object at 0x7f1b010de010>, \'Connection to ***.***.***.*** timed out. (connect timeout=60)\')\n\nDuring handling of the above exception, another exception occurred:\n\nTraceback (most recent call last):\n  File "/app/bazarr/bin/bazarr/../libs/requests/adapters.py", line 489, in send\n    resp = conn.urlopen(\n           ^^^^^^^^^^^^^\n  File "/app/bazarr/bin/bazarr/../libs/urllib3/connectionpool.py", line 787, in urlopen\n    retries = retries.increment(\n              ^^^^^^^^^^^^^^^^^^\n  File "/app/bazarr/bin/bazarr/../libs/urllib3/util/retry.py", line 592, in increment\n    raise MaxRetryError(_pool, url, error or ResponseError(cause))\nurllib3.exceptions.MaxRetryError: HTTPConnectionPool(host=\'***.***.***.***\', port=8989): Max retries exceeded with url: /api/v3/series/?apikey=(removed) (Caused by ConnectTimeoutError(<urllib3.connection.HTTPConnection object at 0x7f1b010de010>, \'Connection to ***.***.***.*** timed out. (connect timeout=60)\'))\n\nDuring handling of the above exception, another exception occurred:\n\nTraceback (most recent call last):\n  File "/app/bazarr/bin/bazarr/sonarr/sync/utils.py", line 74, in get_series_from_sonarr_api\n    r = requests.get(url_sonarr_api_series, timeout=int(settings.sonarr.http_timeout), verify=False, headers=headers)\n        ^^^^^^^^^^^^^^^^^^^^^^^^^^^^^^^^^^^^^^^^^^^^^^^^^^^^^^^^^^^^^^^^^^^^^^^^^^^^^^^^^^^^^^^^^^^^^^^^^^^^^^^^^^^^^\n  File "/app/bazarr/bin/bazarr/../libs/requests/api.py", line 73, in get\n    return request("get", url, params=params, **kwargs)\n           ^^^^^^^^^^^^^^^^^^^^^^^^^^^^^^^^^^^^^^^^^^^^\n  File "/app/bazarr/bin/bazarr/../libs/requests/api.py", line 59, in request\n    return session.request(method=method, url=url, **kwargs)\n           ^^^^^^^^^^^^^^^^^^^^^^^^^^^^^^^^^^^^^^^^^^^^^^^^^\n  File "/app/bazarr/bin/bazarr/../libs/requests/sessions.py", line 587, in request\n    resp = self.send(prep, **send_kwargs)\n           ^^^^^^^^^^^^^^^^^^^^^^^^^^^^^^\n  File "/app/bazarr/bin/bazarr/../libs/requests/sessions.py", line 701, in send\n    r = adapter.send(request, **kwargs)\n        ^^^^^^^^^^^^^^^^^^^^^^^^^^^^^^^\n  File "/app/bazarr/bin/bazarr/../libs/requests/adapters.py", line 553, in send\n    raise ConnectTimeout(e, request=request)\nrequests.exceptions.ConnectTimeout: HTTPConnectionPool(host=\'***.***.***.***\', port=8989): Max retries exceeded with url: /api/v3/series/?apikey=(removed) (Caused by ConnectTimeoutError(<urllib3.connection.HTTPConnection object at 0x7f1b010de010>, \'Connection to ***.***.***.*** timed out. (connect timeout=60)\'))'|
04/01/2024 19:44:22|ERROR   |root                            |BAZARR Error trying to get rootfolder from Sonarr. Connection Error.|'Traceback (most recent call last):\n  File "/app/bazarr/bin/bazarr/../libs/urllib3/connection.py", line 174, in _new_conn\n    conn = connection.create_connection(\n           ^^^^^^^^^^^^^^^^^^^^^^^^^^^^^\n  File "/app/bazarr/bin/bazarr/../libs/subliminal_patch/http.py", line 325, in patched_create_connection\n    return _orig_create_connection(address, *args, **kwargs)\n           ^^^^^^^^^^^^^^^^^^^^^^^^^^^^^^^^^^^^^^^^^^^^^^^^^\n  File "/app/bazarr/bin/bazarr/../libs/urllib3/util/connection.py", line 95, in create_connection\n    raise err\n  File "/app/bazarr/bin/bazarr/../libs/urllib3/util/connection.py", line 85, in create_connection\n    sock.connect(sa)\nTimeoutError: timed out\n\nDuring handling of the above exception, another exception occurred:\n\nTraceback (most recent call last):\n  File "/app/bazarr/bin/bazarr/../libs/urllib3/connectionpool.py", line 703, in urlopen\n    httplib_response = self._make_request(\n                       ^^^^^^^^^^^^^^^^^^^\n  File "/app/bazarr/bin/bazarr/../libs/urllib3/connectionpool.py", line 398, in _make_request\n    conn.request(method, url, **httplib_request_kw)\n  File "/app/bazarr/bin/bazarr/../libs/urllib3/connection.py", line 239, in request\n    super(HTTPConnection, self).request(method, url, body=body, headers=headers)\n  File "/usr/lib/python3.11/http/client.py", line 1286, in request\n    self._send_request(method, url, body, headers, encode_chunked)\n  File "/usr/lib/python3.11/http/client.py", line 1332, in _send_request\n    self.endheaders(body, encode_chunked=encode_chunked)\n  File "/usr/lib/python3.11/http/client.py", line 1281, in endheaders\n    self._send_output(message_body, encode_chunked=encode_chunked)\n  File "/usr/lib/python3.11/http/client.py", line 1041, in _send_output\n    self.send(msg)\n  File "/usr/lib/python3.11/http/client.py", line 979, in send\n    self.connect()\n  File "/app/bazarr/bin/bazarr/../libs/urllib3/connection.py", line 205, in connect\n    conn = self._new_conn()\n           ^^^^^^^^^^^^^^^^\n  File "/app/bazarr/bin/bazarr/../libs/urllib3/connection.py", line 179, in _new_conn\n    raise ConnectTimeoutError(\nurllib3.exceptions.ConnectTimeoutError: (<urllib3.connection.HTTPConnection object at 0x7f1b0109ced0>, \'Connection to ***.***.***.*** timed out. (connect timeout=60)\')\n\nDuring handling of the above exception, another exception occurred:\n\nTraceback (most recent call last):\n  File "/app/bazarr/bin/bazarr/../libs/requests/adapters.py", line 489, in send\n    resp = conn.urlopen(\n           ^^^^^^^^^^^^^\n  File "/app/bazarr/bin/bazarr/../libs/urllib3/connectionpool.py", line 787, in urlopen\n    retries = retries.increment(\n              ^^^^^^^^^^^^^^^^^^\n  File "/app/bazarr/bin/bazarr/../libs/urllib3/util/retry.py", line 592, in increment\n    raise MaxRetryError(_pool, url, error or ResponseError(cause))\nurllib3.exceptions.MaxRetryError: HTTPConnectionPool(host=\'***.***.***.***\', port=8989): Max retries exceeded with url: /api/v3/rootfolder?apikey=(removed) (Caused by ConnectTimeoutError(<urllib3.connection.HTTPConnection object at 0x7f1b0109ced0>, \'Connection to ***.***.***.*** timed out. (connect timeout=60)\'))\n\nDuring handling of the above exception, another exception occurred:\n\nTraceback (most recent call last):\n  File "/app/bazarr/bin/bazarr/sonarr/rootfolder.py", line 22, in get_sonarr_rootfolder\n    rootfolder = requests.get(url_sonarr_api_rootfolder, timeout=int(settings.sonarr.http_timeout), verify=False, headers=headers)\n                 ^^^^^^^^^^^^^^^^^^^^^^^^^^^^^^^^^^^^^^^^^^^^^^^^^^^^^^^^^^^^^^^^^^^^^^^^^^^^^^^^^^^^^^^^^^^^^^^^^^^^^^^^^^^^^^^^^\n  File "/app/bazarr/bin/bazarr/../libs/requests/api.py", line 73, in get\n    return request("get", url, params=params, **kwargs)\n           ^^^^^^^^^^^^^^^^^^^^^^^^^^^^^^^^^^^^^^^^^^^^\n  File "/app/bazarr/bin/bazarr/../libs/requests/api.py", line 59, in request\n    return session.request(method=method, url=url, **kwargs)\n           ^^^^^^^^^^^^^^^^^^^^^^^^^^^^^^^^^^^^^^^^^^^^^^^^^\n  File "/app/bazarr/bin/bazarr/../libs/requests/sessions.py", line 587, in request\n    resp = self.send(prep, **send_kwargs)\n           ^^^^^^^^^^^^^^^^^^^^^^^^^^^^^^\n  File "/app/bazarr/bin/bazarr/../libs/requests/sessions.py", line 701, in send\n    r = adapter.send(request, **kwargs)\n        ^^^^^^^^^^^^^^^^^^^^^^^^^^^^^^^\n  File "/app/bazarr/bin/bazarr/../libs/requests/adapters.py", line 553, in send\n    raise ConnectTimeout(e, request=request)\nrequests.exceptions.ConnectTimeout: HTTPConnectionPool(host=\'***.***.***.***\', port=8989): Max retries exceeded with url: /api/v3/rootfolder?apikey=(removed) (Caused by ConnectTimeoutError(<urllib3.connection.HTTPConnection object at 0x7f1b0109ced0>, \'Connection to ***.***.***.*** timed out. (connect timeout=60)\'))'|
04/01/2024 19:46:22|ERROR   |root                            |BAZARR Error trying to get tags from Sonarr. Connection Error.|'Traceback (most recent call last):\n  File "/app/bazarr/bin/bazarr/../libs/urllib3/connection.py", line 174, in _new_conn\n    conn = connection.create_connection(\n           ^^^^^^^^^^^^^^^^^^^^^^^^^^^^^\n  File "/app/bazarr/bin/bazarr/../libs/subliminal_patch/http.py", line 325, in patched_create_connection\n    return _orig_create_connection(address, *args, **kwargs)\n           ^^^^^^^^^^^^^^^^^^^^^^^^^^^^^^^^^^^^^^^^^^^^^^^^^\n  File "/app/bazarr/bin/bazarr/../libs/urllib3/util/connection.py", line 95, in create_connection\n    raise err\n  File "/app/bazarr/bin/bazarr/../libs/urllib3/util/connection.py", line 85, in create_connection\n    sock.connect(sa)\nTimeoutError: timed out\n\nDuring handling of the above exception, another exception occurred:\n\nTraceback (most recent call last):\n  File "/app/bazarr/bin/bazarr/../libs/urllib3/connectionpool.py", line 703, in urlopen\n    httplib_response = self._make_request(\n                       ^^^^^^^^^^^^^^^^^^^\n  File "/app/bazarr/bin/bazarr/../libs/urllib3/connectionpool.py", line 398, in _make_request\n    conn.request(method, url, **httplib_request_kw)\n  File "/app/bazarr/bin/bazarr/../libs/urllib3/connection.py", line 239, in request\n    super(HTTPConnection, self).request(method, url, body=body, headers=headers)\n  File "/usr/lib/python3.11/http/client.py", line 1286, in request\n    self._send_request(method, url, body, headers, encode_chunked)\n  File "/usr/lib/python3.11/http/client.py", line 1332, in _send_request\n    self.endheaders(body, encode_chunked=encode_chunked)\n  File "/usr/lib/python3.11/http/client.py", line 1281, in endheaders\n    self._send_output(message_body, encode_chunked=encode_chunked)\n  File "/usr/lib/python3.11/http/client.py", line 1041, in _send_output\n    self.send(msg)\n  File "/usr/lib/python3.11/http/client.py", line 979, in send\n    self.connect()\n  File "/app/bazarr/bin/bazarr/../libs/urllib3/connection.py", line 205, in connect\n    conn = self._new_conn()\n           ^^^^^^^^^^^^^^^^\n  File "/app/bazarr/bin/bazarr/../libs/urllib3/connection.py", line 179, in _new_conn\n    raise ConnectTimeoutError(\nurllib3.exceptions.ConnectTimeoutError: (<urllib3.connection.HTTPConnection object at 0x7f1b010ea5d0>, \'Connection to ***.***.***.*** timed out. (connect timeout=60)\')\n\nDuring handling of the above exception, another exception occurred:\n\nTraceback (most recent call last):\n  File "/app/bazarr/bin/bazarr/../libs/requests/adapters.py", line 489, in send\n    resp = conn.urlopen(\n           ^^^^^^^^^^^^^\n  File "/app/bazarr/bin/bazarr/../libs/urllib3/connectionpool.py", line 787, in urlopen\n    retries = retries.increment(\n              ^^^^^^^^^^^^^^^^^^\n  File "/app/bazarr/bin/bazarr/../libs/urllib3/util/retry.py", line 592, in increment\n    raise MaxRetryError(_pool, url, error or ResponseError(cause))\nurllib3.exceptions.MaxRetryError: HTTPConnectionPool(host=\'***.***.***.***\', port=8989): Max retries exceeded with url: /api/v3/tag?apikey=(removed) (Caused by ConnectTimeoutError(<urllib3.connection.HTTPConnection object at 0x7f1b010ea5d0>, \'Connection to ***.***.***.*** timed out. (connect timeout=60)\'))\n\nDuring handling of the above exception, another exception occurred:\n\nTraceback (most recent call last):\n  File "/app/bazarr/bin/bazarr/sonarr/sync/utils.py", line 56, in get_tags\n    tagsDict = requests.get(url_sonarr_api_series, timeout=int(settings.sonarr.http_timeout), verify=False, headers=headers)\n               ^^^^^^^^^^^^^^^^^^^^^^^^^^^^^^^^^^^^^^^^^^^^^^^^^^^^^^^^^^^^^^^^^^^^^^^^^^^^^^^^^^^^^^^^^^^^^^^^^^^^^^^^^^^^^\n  File "/app/bazarr/bin/bazarr/../libs/requests/api.py", line 73, in get\n    return request("get", url, params=params, **kwargs)\n           ^^^^^^^^^^^^^^^^^^^^^^^^^^^^^^^^^^^^^^^^^^^^\n  File "/app/bazarr/bin/bazarr/../libs/requests/api.py", line 59, in request\n    return session.request(method=method, url=url, **kwargs)\n           ^^^^^^^^^^^^^^^^^^^^^^^^^^^^^^^^^^^^^^^^^^^^^^^^^\n  File "/app/bazarr/bin/bazarr/../libs/requests/sessions.py", line 587, in request\n    resp = self.send(prep, **send_kwargs)\n           ^^^^^^^^^^^^^^^^^^^^^^^^^^^^^^\n  File "/app/bazarr/bin/bazarr/../libs/requests/sessions.py", line 701, in send\n    r = adapter.send(request, **kwargs)\n        ^^^^^^^^^^^^^^^^^^^^^^^^^^^^^^^\n  File "/app/bazarr/bin/bazarr/../libs/requests/adapters.py", line 553, in send\n    raise ConnectTimeout(e, request=request)\nrequests.exceptions.ConnectTimeout: HTTPConnectionPool(host=\'***.***.***.***\', port=8989): Max retries exceeded with url: /api/v3/tag?apikey=(removed) (Caused by ConnectTimeoutError(<urllib3.connection.HTTPConnection object at 0x7f1b010ea5d0>, \'Connection to ***.***.***.*** timed out. (connect timeout=60)\'))'|
04/01/2024 19:48:22|ERROR   |root                            |BAZARR Error trying to get series from Sonarr. Connection Error.|'Traceback (most recent call last):\n  File "/app/bazarr/bin/bazarr/../libs/urllib3/connection.py", line 174, in _new_conn\n    conn = connection.create_connection(\n           ^^^^^^^^^^^^^^^^^^^^^^^^^^^^^\n  File "/app/bazarr/bin/bazarr/../libs/subliminal_patch/http.py", line 325, in patched_create_connection\n    return _orig_create_connection(address, *args, **kwargs)\n           ^^^^^^^^^^^^^^^^^^^^^^^^^^^^^^^^^^^^^^^^^^^^^^^^^\n  File "/app/bazarr/bin/bazarr/../libs/urllib3/util/connection.py", line 95, in create_connection\n    raise err\n  File "/app/bazarr/bin/bazarr/../libs/urllib3/util/connection.py", line 85, in create_connection\n    sock.connect(sa)\nTimeoutError: timed out\n\nDuring handling of the above exception, another exception occurred:\n\nTraceback (most recent call last):\n  File "/app/bazarr/bin/bazarr/../libs/urllib3/connectionpool.py", line 703, in urlopen\n    httplib_response = self._make_request(\n                       ^^^^^^^^^^^^^^^^^^^\n  File "/app/bazarr/bin/bazarr/../libs/urllib3/connectionpool.py", line 398, in _make_request\n    conn.request(method, url, **httplib_request_kw)\n  File "/app/bazarr/bin/bazarr/../libs/urllib3/connection.py", line 239, in request\n    super(HTTPConnection, self).request(method, url, body=body, headers=headers)\n  File "/usr/lib/python3.11/http/client.py", line 1286, in request\n    self._send_request(method, url, body, headers, encode_chunked)\n  File "/usr/lib/python3.11/http/client.py", line 1332, in _send_request\n    self.endheaders(body, encode_chunked=encode_chunked)\n  File "/usr/lib/python3.11/http/client.py", line 1281, in endheaders\n    self._send_output(message_body, encode_chunked=encode_chunked)\n  File "/usr/lib/python3.11/http/client.py", line 1041, in _send_output\n    self.send(msg)\n  File "/usr/lib/python3.11/http/client.py", line 979, in send\n    self.connect()\n  File "/app/bazarr/bin/bazarr/../libs/urllib3/connection.py", line 205, in connect\n    conn = self._new_conn()\n           ^^^^^^^^^^^^^^^^\n  File "/app/bazarr/bin/bazarr/../libs/urllib3/connection.py", line 179, in _new_conn\n    raise ConnectTimeoutError(\nurllib3.exceptions.ConnectTimeoutError: (<urllib3.connection.HTTPConnection object at 0x7f1b0109c350>, \'Connection to ***.***.***.*** timed out. (connect timeout=60)\')\n\nDuring handling of the above exception, another exception occurred:\n\nTraceback (most recent call last):\n  File "/app/bazarr/bin/bazarr/../libs/requests/adapters.py", line 489, in send\n    resp = conn.urlopen(\n           ^^^^^^^^^^^^^\n  File "/app/bazarr/bin/bazarr/../libs/urllib3/connectionpool.py", line 787, in urlopen\n    retries = retries.increment(\n              ^^^^^^^^^^^^^^^^^^\n  File "/app/bazarr/bin/bazarr/../libs/urllib3/util/retry.py", line 592, in increment\n    raise MaxRetryError(_pool, url, error or ResponseError(cause))\nurllib3.exceptions.MaxRetryError: HTTPConnectionPool(host=\'***.***.***.***\', port=8989): Max retries exceeded with url: /api/v3/series/?apikey=(removed) (Caused by ConnectTimeoutError(<urllib3.connection.HTTPConnection object at 0x7f1b0109c350>, \'Connection to ***.***.***.*** timed out. (connect timeout=60)\'))\n\nDuring handling of the above exception, another exception occurred:\n\nTraceback (most recent call last):\n  File "/app/bazarr/bin/bazarr/sonarr/sync/utils.py", line 74, in get_series_from_sonarr_api\n    r = requests.get(url_sonarr_api_series, timeout=int(settings.sonarr.http_timeout), verify=False, headers=headers)\n        ^^^^^^^^^^^^^^^^^^^^^^^^^^^^^^^^^^^^^^^^^^^^^^^^^^^^^^^^^^^^^^^^^^^^^^^^^^^^^^^^^^^^^^^^^^^^^^^^^^^^^^^^^^^^^\n  File "/app/bazarr/bin/bazarr/../libs/requests/api.py", line 73, in get\n    return request("get", url, params=params, **kwargs)\n           ^^^^^^^^^^^^^^^^^^^^^^^^^^^^^^^^^^^^^^^^^^^^\n  File "/app/bazarr/bin/bazarr/../libs/requests/api.py", line 59, in request\n    return session.request(method=method, url=url, **kwargs)\n           ^^^^^^^^^^^^^^^^^^^^^^^^^^^^^^^^^^^^^^^^^^^^^^^^^\n  File "/app/bazarr/bin/bazarr/../libs/requests/sessions.py", line 587, in request\n    resp = self.send(prep, **send_kwargs)\n           ^^^^^^^^^^^^^^^^^^^^^^^^^^^^^^\n  File "/app/bazarr/bin/bazarr/../libs/requests/sessions.py", line 701, in send\n    r = adapter.send(request, **kwargs)\n        ^^^^^^^^^^^^^^^^^^^^^^^^^^^^^^^\n  File "/app/bazarr/bin/bazarr/../libs/requests/adapters.py", line 553, in send\n    raise ConnectTimeout(e, request=request)\nrequests.exceptions.ConnectTimeout: HTTPConnectionPool(host=\'***.***.***.***\', port=8989): Max retries exceeded with url: /api/v3/series/?apikey=(removed) (Caused by ConnectTimeoutError(<urllib3.connection.HTTPConnection object at 0x7f1b0109c350>, \'Connection to ***.***.***.*** timed out. (connect timeout=60)\'))'|
04/01/2024 19:59:22|ERROR   |root                            |BAZARR Error trying to get rootfolder from Sonarr. Connection Error.|'Traceback (most recent call last):\n  File "/app/bazarr/bin/bazarr/../libs/urllib3/connection.py", line 174, in _new_conn\n    conn = connection.create_connection(\n           ^^^^^^^^^^^^^^^^^^^^^^^^^^^^^\n  File "/app/bazarr/bin/bazarr/../libs/subliminal_patch/http.py", line 325, in patched_create_connection\n    return _orig_create_connection(address, *args, **kwargs)\n           ^^^^^^^^^^^^^^^^^^^^^^^^^^^^^^^^^^^^^^^^^^^^^^^^^\n  File "/app/bazarr/bin/bazarr/../libs/urllib3/util/connection.py", line 95, in create_connection\n    raise err\n  File "/app/bazarr/bin/bazarr/../libs/urllib3/util/connection.py", line 85, in create_connection\n    sock.connect(sa)\nTimeoutError: timed out\n\nDuring handling of the above exception, another exception occurred:\n\nTraceback (most recent call last):\n  File "/app/bazarr/bin/bazarr/../libs/urllib3/connectionpool.py", line 703, in urlopen\n    httplib_response = self._make_request(\n                       ^^^^^^^^^^^^^^^^^^^\n  File "/app/bazarr/bin/bazarr/../libs/urllib3/connectionpool.py", line 398, in _make_request\n    conn.request(method, url, **httplib_request_kw)\n  File "/app/bazarr/bin/bazarr/../libs/urllib3/connection.py", line 239, in request\n    super(HTTPConnection, self).request(method, url, body=body, headers=headers)\n  File "/usr/lib/python3.11/http/client.py", line 1286, in request\n    self._send_request(method, url, body, headers, encode_chunked)\n  File "/usr/lib/python3.11/http/client.py", line 1332, in _send_request\n    self.endheaders(body, encode_chunked=encode_chunked)\n  File "/usr/lib/python3.11/http/client.py", line 1281, in endheaders\n    self._send_output(message_body, encode_chunked=encode_chunked)\n  File "/usr/lib/python3.11/http/client.py", line 1041, in _send_output\n    self.send(msg)\n  File "/usr/lib/python3.11/http/client.py", line 979, in send\n    self.connect()\n  File "/app/bazarr/bin/bazarr/../libs/urllib3/connection.py", line 205, in connect\n    conn = self._new_conn()\n           ^^^^^^^^^^^^^^^^\n  File "/app/bazarr/bin/bazarr/../libs/urllib3/connection.py", line 179, in _new_conn\n    raise ConnectTimeoutError(\nurllib3.exceptions.ConnectTimeoutError: (<urllib3.connection.HTTPConnection object at 0x7f1b01047f90>, \'Connection to ***.***.***.*** timed out. (connect timeout=60)\')\n\nDuring handling of the above exception, another exception occurred:\n\nTraceback (most recent call last):\n  File "/app/bazarr/bin/bazarr/../libs/requests/adapters.py", line 489, in send\n    resp = conn.urlopen(\n           ^^^^^^^^^^^^^\n  File "/app/bazarr/bin/bazarr/../libs/urllib3/connectionpool.py", line 787, in urlopen\n    retries = retries.increment(\n              ^^^^^^^^^^^^^^^^^^\n  File "/app/bazarr/bin/bazarr/../libs/urllib3/util/retry.py", line 592, in increment\n    raise MaxRetryError(_pool, url, error or ResponseError(cause))\nurllib3.exceptions.MaxRetryError: HTTPConnectionPool(host=\'***.***.***.***\', port=8989): Max retries exceeded with url: /api/v3/rootfolder?apikey=(removed) (Caused by ConnectTimeoutError(<urllib3.connection.HTTPConnection object at 0x7f1b01047f90>, \'Connection to ***.***.***.*** timed out. (connect timeout=60)\'))\n\nDuring handling of the above exception, another exception occurred:\n\nTraceback (most recent call last):\n  File "/app/bazarr/bin/bazarr/sonarr/rootfolder.py", line 22, in get_sonarr_rootfolder\n    rootfolder = requests.get(url_sonarr_api_rootfolder, timeout=int(settings.sonarr.http_timeout), verify=False, headers=headers)\n                 ^^^^^^^^^^^^^^^^^^^^^^^^^^^^^^^^^^^^^^^^^^^^^^^^^^^^^^^^^^^^^^^^^^^^^^^^^^^^^^^^^^^^^^^^^^^^^^^^^^^^^^^^^^^^^^^^^\n  File "/app/bazarr/bin/bazarr/../libs/requests/api.py", line 73, in get\n    return request("get", url, params=params, **kwargs)\n           ^^^^^^^^^^^^^^^^^^^^^^^^^^^^^^^^^^^^^^^^^^^^\n  File "/app/bazarr/bin/bazarr/../libs/requests/api.py", line 59, in request\n    return session.request(method=method, url=url, **kwargs)\n           ^^^^^^^^^^^^^^^^^^^^^^^^^^^^^^^^^^^^^^^^^^^^^^^^^\n  File "/app/bazarr/bin/bazarr/../libs/requests/sessions.py", line 587, in request\n    resp = self.send(prep, **send_kwargs)\n           ^^^^^^^^^^^^^^^^^^^^^^^^^^^^^^\n  File "/app/bazarr/bin/bazarr/../libs/requests/sessions.py", line 701, in send\n    r = adapter.send(request, **kwargs)\n        ^^^^^^^^^^^^^^^^^^^^^^^^^^^^^^^\n  File "/app/bazarr/bin/bazarr/../libs/requests/adapters.py", line 553, in send\n    raise ConnectTimeout(e, request=request)\nrequests.exceptions.ConnectTimeout: HTTPConnectionPool(host=\'***.***.***.***\', port=8989): Max retries exceeded with url: /api/v3/rootfolder?apikey=(removed) (Caused by ConnectTimeoutError(<urllib3.connection.HTTPConnection object at 0x7f1b01047f90>, \'Connection to ***.***.***.*** timed out. (connect timeout=60)\'))'|
04/01/2024 20:01:22|ERROR   |root                            |BAZARR Error trying to get tags from Sonarr. Connection Error.|'Traceback (most recent call last):\n  File "/app/bazarr/bin/bazarr/../libs/urllib3/connection.py", line 174, in _new_conn\n    conn = connection.create_connection(\n           ^^^^^^^^^^^^^^^^^^^^^^^^^^^^^\n  File "/app/bazarr/bin/bazarr/../libs/subliminal_patch/http.py", line 325, in patched_create_connection\n    return _orig_create_connection(address, *args, **kwargs)\n           ^^^^^^^^^^^^^^^^^^^^^^^^^^^^^^^^^^^^^^^^^^^^^^^^^\n  File "/app/bazarr/bin/bazarr/../libs/urllib3/util/connection.py", line 95, in create_connection\n    raise err\n  File "/app/bazarr/bin/bazarr/../libs/urllib3/util/connection.py", line 85, in create_connection\n    sock.connect(sa)\nTimeoutError: timed out\n\nDuring handling of the above exception, another exception occurred:\n\nTraceback (most recent call last):\n  File "/app/bazarr/bin/bazarr/../libs/urllib3/connectionpool.py", line 703, in urlopen\n    httplib_response = self._make_request(\n                       ^^^^^^^^^^^^^^^^^^^\n  File "/app/bazarr/bin/bazarr/../libs/urllib3/connectionpool.py", line 398, in _make_request\n    conn.request(method, url, **httplib_request_kw)\n  File "/app/bazarr/bin/bazarr/../libs/urllib3/connection.py", line 239, in request\n    super(HTTPConnection, self).request(method, url, body=body, headers=headers)\n  File "/usr/lib/python3.11/http/client.py", line 1286, in request\n    self._send_request(method, url, body, headers, encode_chunked)\n  File "/usr/lib/python3.11/http/client.py", line 1332, in _send_request\n    self.endheaders(body, encode_chunked=encode_chunked)\n  File "/usr/lib/python3.11/http/client.py", line 1281, in endheaders\n    self._send_output(message_body, encode_chunked=encode_chunked)\n  File "/usr/lib/python3.11/http/client.py", line 1041, in _send_output\n    self.send(msg)\n  File "/usr/lib/python3.11/http/client.py", line 979, in send\n    self.connect()\n  File "/app/bazarr/bin/bazarr/../libs/urllib3/connection.py", line 205, in connect\n    conn = self._new_conn()\n           ^^^^^^^^^^^^^^^^\n  File "/app/bazarr/bin/bazarr/../libs/urllib3/connection.py", line 179, in _new_conn\n    raise ConnectTimeoutError(\nurllib3.exceptions.ConnectTimeoutError: (<urllib3.connection.HTTPConnection object at 0x7f1b0f1013d0>, \'Connection to ***.***.***.*** timed out. (connect timeout=60)\')\n\nDuring handling of the above exception, another exception occurred:\n\nTraceback (most recent call last):\n  File "/app/bazarr/bin/bazarr/../libs/requests/adapters.py", line 489, in send\n    resp = conn.urlopen(\n           ^^^^^^^^^^^^^\n  File "/app/bazarr/bin/bazarr/../libs/urllib3/connectionpool.py", line 787, in urlopen\n    retries = retries.increment(\n              ^^^^^^^^^^^^^^^^^^\n  File "/app/bazarr/bin/bazarr/../libs/urllib3/util/retry.py", line 592, in increment\n    raise MaxRetryError(_pool, url, error or ResponseError(cause))\nurllib3.exceptions.MaxRetryError: HTTPConnectionPool(host=\'***.***.***.***\', port=8989): Max retries exceeded with url: /api/v3/tag?apikey=(removed) (Caused by ConnectTimeoutError(<urllib3.connection.HTTPConnection object at 0x7f1b0f1013d0>, \'Connection to ***.***.***.*** timed out. (connect timeout=60)\'))\n\nDuring handling of the above exception, another exception occurred:\n\nTraceback (most recent call last):\n  File "/app/bazarr/bin/bazarr/sonarr/sync/utils.py", line 56, in get_tags\n    tagsDict = requests.get(url_sonarr_api_series, timeout=int(settings.sonarr.http_timeout), verify=False, headers=headers)\n               ^^^^^^^^^^^^^^^^^^^^^^^^^^^^^^^^^^^^^^^^^^^^^^^^^^^^^^^^^^^^^^^^^^^^^^^^^^^^^^^^^^^^^^^^^^^^^^^^^^^^^^^^^^^^^\n  File "/app/bazarr/bin/bazarr/../libs/requests/api.py", line 73, in get\n    return request("get", url, params=params, **kwargs)\n           ^^^^^^^^^^^^^^^^^^^^^^^^^^^^^^^^^^^^^^^^^^^^\n  File "/app/bazarr/bin/bazarr/../libs/requests/api.py", line 59, in request\n    return session.request(method=method, url=url, **kwargs)\n           ^^^^^^^^^^^^^^^^^^^^^^^^^^^^^^^^^^^^^^^^^^^^^^^^^\n  File "/app/bazarr/bin/bazarr/../libs/requests/sessions.py", line 587, in request\n    resp = self.send(prep, **send_kwargs)\n           ^^^^^^^^^^^^^^^^^^^^^^^^^^^^^^\n  File "/app/bazarr/bin/bazarr/../libs/requests/sessions.py", line 701, in send\n    r = adapter.send(request, **kwargs)\n        ^^^^^^^^^^^^^^^^^^^^^^^^^^^^^^^\n  File "/app/bazarr/bin/bazarr/../libs/requests/adapters.py", line 553, in send\n    raise ConnectTimeout(e, request=request)\nrequests.exceptions.ConnectTimeout: HTTPConnectionPool(host=\'***.***.***.***\', port=8989): Max retries exceeded with url: /api/v3/tag?apikey=(removed) (Caused by ConnectTimeoutError(<urllib3.connection.HTTPConnection object at 0x7f1b0f1013d0>, \'Connection to ***.***.***.*** timed out. (connect timeout=60)\'))'|
04/01/2024 20:04:36|INFO    |root                            |BAZARR trying to connect to Sonarr SignalR feed...|
04/01/2024 20:04:36|INFO    |root                            |BAZARR is started and waiting for request on http://***.***.***.***:6767|
04/01/2024 20:18:12|INFO    |root                            |BAZARR trying to connect to Sonarr SignalR feed...|
04/01/2024 20:19:41|WARNING |retry.api                       |HTTPSConnectionPool(host='www.podnapisi.net', port=443): Read timed out. (read timeout=10), retrying in 5 seconds...|
04/01/2024 20:42:17|INFO    |root                            |BAZARR trying to connect to Sonarr SignalR feed...|
04/01/2024 20:42:17|INFO    |root                            |BAZARR is started and waiting for request on http://***.***.***.***:6767|
04/01/2024 20:42:37|INFO    |root                            |BAZARR trying to connect to Sonarr SignalR feed...|
04/01/2024 20:42:37|INFO    |root                            |BAZARR is started and waiting for request on http://***.***.***.***:6767|
04/01/2024 20:44:31|INFO    |root                            |BAZARR trying to connect to Sonarr SignalR feed...|
04/01/2024 20:44:31|INFO    |root                            |BAZARR is started and waiting for request on http://***.***.***.***:6767|
04/01/2024 20:44:31|INFO    |root                            |BAZARR SignalR client for Sonarr is connected and waiting for events.|
04/01/2024 20:53:19|INFO    |root                            |BAZARR trying to connect to Sonarr SignalR feed...|
04/01/2024 20:53:19|INFO    |root                            |BAZARR is started and waiting for request on http://***.***.***.***:6767|
04/01/2024 20:53:19|INFO    |root                            |BAZARR SignalR client for Sonarr is connected and waiting for events.|
04/01/2024 21:10:06|INFO    |root                            |BAZARR trying to connect to Radarr SignalR feed...|
04/01/2024 21:10:25|INFO    |root                            |BAZARR trying to connect to Radarr SignalR feed...|
04/01/2024 21:10:25|INFO    |root                            |BAZARR SignalR client for Radarr is connected and waiting for events.|
04/01/2024 21:44:11|INFO    |root                            |Throttling subf2m for 12 hours, until 24/01/05 09:44, because of: ConfigurationError. Exception info: "'User-agent config missing' ~ subf2m.py@159"|
04/01/2024 21:44:34|INFO    |root                            |Throttling opensubtitles for 12 hours, until 24/01/05 09:44, because of: PaymentRequired. Exception info: "'' ~ opensubtitles.py@422"|
04/01/2024 21:44:47|WARNING |retry.api                       |HTTPSConnectionPool(host='www.podnapisi.net', port=443): Read timed out. (read timeout=10), retrying in 5 seconds...|
